2023-06-14 12:09:43,068 - app - ERROR - this is an error
2023-06-14 13:00:09,320 - app - ERROR - this is an error
2023-06-15 22:57:51,549 - werkzeug - ERROR - 127.0.0.1 - - [15/Jun/2023 22:57:51] code 400, message Bad request version ('\x13\x01\x13\x02\x13\x03À+À,Ì©À/À0Ì¨À\x13À\x14\x00\x9c\x00\x9d\x00/\x005\x01\x00\x01\x95\x00\x00\x00\x17\x00\x15\x00\x00\x1228m8152x58.goho.co\x00\x17\x00\x00ÿ\x01\x00\x01\x00\x00')
2023-06-15 22:57:55,006 - werkzeug - ERROR - 127.0.0.1 - - [15/Jun/2023 22:57:55] code 400, message Bad request version ('°\x0eÏÏ\\\x0f\x0fm|\x94c\x07\x8c\x05tÐÜ±°¦\x19\x07\x0f\x12®j\x83Ù@¶x')
2023-06-15 22:57:58,278 - werkzeug - ERROR - 127.0.0.1 - - [15/Jun/2023 22:57:58] code 400, message Bad request version ('\x13\x01\x13\x02\x13\x03À+À,Ì©À/À0Ì¨À\x13À\x14\x00\x9c\x00\x9d\x00/\x005\x01\x00\x01\x95\x00\x00\x00\x17\x00\x15\x00\x00\x1228m8152x58.goho.co\x00\x17\x00\x00ÿ\x01\x00\x01\x00\x00')
2023-06-15 23:00:02,835 - app - ERROR - Exception on /code [GET]
Traceback (most recent call last):
  File "C:\Users\UltAshes\AppData\Roaming\Python\Python310\site-packages\redis\connection.py", line 699, in connect
    sock = self.retry.call_with_retry(
  File "C:\Users\UltAshes\AppData\Roaming\Python\Python310\site-packages\redis\retry.py", line 46, in call_with_retry
    return do()
  File "C:\Users\UltAshes\AppData\Roaming\Python\Python310\site-packages\redis\connection.py", line 700, in <lambda>
    lambda: self._connect(), lambda error: self.disconnect(error)
  File "C:\Users\UltAshes\AppData\Roaming\Python\Python310\site-packages\redis\connection.py", line 1002, in _connect
    raise err
  File "C:\Users\UltAshes\AppData\Roaming\Python\Python310\site-packages\redis\connection.py", line 990, in _connect
    sock.connect(socket_address)
ConnectionRefusedError: [WinError 10061] 由于目标计算机积极拒绝，无法连接。

During handling of the above exception, another exception occurred:

Traceback (most recent call last):
  File "C:\Users\UltAshes\AppData\Local\Programs\Python\Python310\lib\site-packages\flask\app.py", line 2525, in wsgi_app
    response = self.full_dispatch_request()
  File "C:\Users\UltAshes\AppData\Local\Programs\Python\Python310\lib\site-packages\flask\app.py", line 1822, in full_dispatch_request
    rv = self.handle_user_exception(e)
  File "C:\Users\UltAshes\AppData\Local\Programs\Python\Python310\lib\site-packages\flask_cors\extension.py", line 165, in wrapped_function
    return cors_after_request(app.make_response(f(*args, **kwargs)))
  File "C:\Users\UltAshes\AppData\Local\Programs\Python\Python310\lib\site-packages\flask\app.py", line 1820, in full_dispatch_request
    rv = self.dispatch_request()
  File "C:\Users\UltAshes\AppData\Local\Programs\Python\Python310\lib\site-packages\flask\app.py", line 1796, in dispatch_request
    return self.ensure_sync(self.view_functions[rule.endpoint])(**view_args)
  File "C:\Users\UltAshes\Desktop\youxi-main2\app\main\view.py", line 31, in code
    redis_store.set("code", b, 60)
  File "C:\Users\UltAshes\AppData\Roaming\Python\Python310\site-packages\redis\commands\core.py", line 2313, in set
    return self.execute_command("SET", *pieces, **options)
  File "C:\Users\UltAshes\AppData\Roaming\Python\Python310\site-packages\redis\client.py", line 1266, in execute_command
    conn = self.connection or pool.get_connection(command_name, **options)
  File "C:\Users\UltAshes\AppData\Roaming\Python\Python310\site-packages\redis\connection.py", line 1457, in get_connection
    connection.connect()
  File "C:\Users\UltAshes\AppData\Roaming\Python\Python310\site-packages\redis\connection.py", line 705, in connect
    raise ConnectionError(self._error_message(e))
redis.exceptions.ConnectionError: Error 10061 connecting to 127.0.0.1:6379. 由于目标计算机积极拒绝，无法连接。.
2023-06-15 23:00:29,151 - app - ERROR - Exception on /code [GET]
Traceback (most recent call last):
  File "C:\Users\UltAshes\AppData\Roaming\Python\Python310\site-packages\redis\connection.py", line 699, in connect
    sock = self.retry.call_with_retry(
  File "C:\Users\UltAshes\AppData\Roaming\Python\Python310\site-packages\redis\retry.py", line 46, in call_with_retry
    return do()
  File "C:\Users\UltAshes\AppData\Roaming\Python\Python310\site-packages\redis\connection.py", line 700, in <lambda>
    lambda: self._connect(), lambda error: self.disconnect(error)
  File "C:\Users\UltAshes\AppData\Roaming\Python\Python310\site-packages\redis\connection.py", line 1002, in _connect
    raise err
  File "C:\Users\UltAshes\AppData\Roaming\Python\Python310\site-packages\redis\connection.py", line 990, in _connect
    sock.connect(socket_address)
ConnectionRefusedError: [WinError 10061] 由于目标计算机积极拒绝，无法连接。

During handling of the above exception, another exception occurred:

Traceback (most recent call last):
  File "C:\Users\UltAshes\AppData\Local\Programs\Python\Python310\lib\site-packages\flask\app.py", line 2525, in wsgi_app
    response = self.full_dispatch_request()
  File "C:\Users\UltAshes\AppData\Local\Programs\Python\Python310\lib\site-packages\flask\app.py", line 1822, in full_dispatch_request
    rv = self.handle_user_exception(e)
  File "C:\Users\UltAshes\AppData\Local\Programs\Python\Python310\lib\site-packages\flask_cors\extension.py", line 165, in wrapped_function
    return cors_after_request(app.make_response(f(*args, **kwargs)))
  File "C:\Users\UltAshes\AppData\Local\Programs\Python\Python310\lib\site-packages\flask\app.py", line 1820, in full_dispatch_request
    rv = self.dispatch_request()
  File "C:\Users\UltAshes\AppData\Local\Programs\Python\Python310\lib\site-packages\flask\app.py", line 1796, in dispatch_request
    return self.ensure_sync(self.view_functions[rule.endpoint])(**view_args)
  File "C:\Users\UltAshes\Desktop\youxi-main2\app\main\view.py", line 31, in code
    redis_store.set("code", b, 60)
  File "C:\Users\UltAshes\AppData\Roaming\Python\Python310\site-packages\redis\commands\core.py", line 2313, in set
    return self.execute_command("SET", *pieces, **options)
  File "C:\Users\UltAshes\AppData\Roaming\Python\Python310\site-packages\redis\client.py", line 1266, in execute_command
    conn = self.connection or pool.get_connection(command_name, **options)
  File "C:\Users\UltAshes\AppData\Roaming\Python\Python310\site-packages\redis\connection.py", line 1457, in get_connection
    connection.connect()
  File "C:\Users\UltAshes\AppData\Roaming\Python\Python310\site-packages\redis\connection.py", line 705, in connect
    raise ConnectionError(self._error_message(e))
redis.exceptions.ConnectionError: Error 10061 connecting to 127.0.0.1:6379. 由于目标计算机积极拒绝，无法连接。.
2023-06-15 23:00:54,536 - app - ERROR - Exception on /code [GET]
Traceback (most recent call last):
  File "C:\Users\UltAshes\AppData\Roaming\Python\Python310\site-packages\redis\connection.py", line 699, in connect
    sock = self.retry.call_with_retry(
  File "C:\Users\UltAshes\AppData\Roaming\Python\Python310\site-packages\redis\retry.py", line 46, in call_with_retry
    return do()
  File "C:\Users\UltAshes\AppData\Roaming\Python\Python310\site-packages\redis\connection.py", line 700, in <lambda>
    lambda: self._connect(), lambda error: self.disconnect(error)
  File "C:\Users\UltAshes\AppData\Roaming\Python\Python310\site-packages\redis\connection.py", line 1002, in _connect
    raise err
  File "C:\Users\UltAshes\AppData\Roaming\Python\Python310\site-packages\redis\connection.py", line 990, in _connect
    sock.connect(socket_address)
ConnectionRefusedError: [WinError 10061] 由于目标计算机积极拒绝，无法连接。

During handling of the above exception, another exception occurred:

Traceback (most recent call last):
  File "C:\Users\UltAshes\AppData\Local\Programs\Python\Python310\lib\site-packages\flask\app.py", line 2525, in wsgi_app
    response = self.full_dispatch_request()
  File "C:\Users\UltAshes\AppData\Local\Programs\Python\Python310\lib\site-packages\flask\app.py", line 1822, in full_dispatch_request
    rv = self.handle_user_exception(e)
  File "C:\Users\UltAshes\AppData\Local\Programs\Python\Python310\lib\site-packages\flask_cors\extension.py", line 165, in wrapped_function
    return cors_after_request(app.make_response(f(*args, **kwargs)))
  File "C:\Users\UltAshes\AppData\Local\Programs\Python\Python310\lib\site-packages\flask\app.py", line 1820, in full_dispatch_request
    rv = self.dispatch_request()
  File "C:\Users\UltAshes\AppData\Local\Programs\Python\Python310\lib\site-packages\flask\app.py", line 1796, in dispatch_request
    return self.ensure_sync(self.view_functions[rule.endpoint])(**view_args)
  File "C:\Users\UltAshes\Desktop\youxi-main2\app\main\view.py", line 31, in code
    redis_store.set("code", b, 60)
  File "C:\Users\UltAshes\AppData\Roaming\Python\Python310\site-packages\redis\commands\core.py", line 2313, in set
    return self.execute_command("SET", *pieces, **options)
  File "C:\Users\UltAshes\AppData\Roaming\Python\Python310\site-packages\redis\client.py", line 1266, in execute_command
    conn = self.connection or pool.get_connection(command_name, **options)
  File "C:\Users\UltAshes\AppData\Roaming\Python\Python310\site-packages\redis\connection.py", line 1457, in get_connection
    connection.connect()
  File "C:\Users\UltAshes\AppData\Roaming\Python\Python310\site-packages\redis\connection.py", line 705, in connect
    raise ConnectionError(self._error_message(e))
redis.exceptions.ConnectionError: Error 10061 connecting to 127.0.0.1:6379. 由于目标计算机积极拒绝，无法连接。.
2023-06-15 23:02:08,827 - app - ERROR - Exception on /code [GET]
Traceback (most recent call last):
  File "C:\Users\UltAshes\AppData\Roaming\Python\Python310\site-packages\redis\connection.py", line 699, in connect
    sock = self.retry.call_with_retry(
  File "C:\Users\UltAshes\AppData\Roaming\Python\Python310\site-packages\redis\retry.py", line 46, in call_with_retry
    return do()
  File "C:\Users\UltAshes\AppData\Roaming\Python\Python310\site-packages\redis\connection.py", line 700, in <lambda>
    lambda: self._connect(), lambda error: self.disconnect(error)
  File "C:\Users\UltAshes\AppData\Roaming\Python\Python310\site-packages\redis\connection.py", line 1002, in _connect
    raise err
  File "C:\Users\UltAshes\AppData\Roaming\Python\Python310\site-packages\redis\connection.py", line 990, in _connect
    sock.connect(socket_address)
ConnectionRefusedError: [WinError 10061] 由于目标计算机积极拒绝，无法连接。

During handling of the above exception, another exception occurred:

Traceback (most recent call last):
  File "C:\Users\UltAshes\AppData\Local\Programs\Python\Python310\lib\site-packages\flask\app.py", line 2525, in wsgi_app
    response = self.full_dispatch_request()
  File "C:\Users\UltAshes\AppData\Local\Programs\Python\Python310\lib\site-packages\flask\app.py", line 1822, in full_dispatch_request
    rv = self.handle_user_exception(e)
  File "C:\Users\UltAshes\AppData\Local\Programs\Python\Python310\lib\site-packages\flask_cors\extension.py", line 165, in wrapped_function
    return cors_after_request(app.make_response(f(*args, **kwargs)))
  File "C:\Users\UltAshes\AppData\Local\Programs\Python\Python310\lib\site-packages\flask\app.py", line 1820, in full_dispatch_request
    rv = self.dispatch_request()
  File "C:\Users\UltAshes\AppData\Local\Programs\Python\Python310\lib\site-packages\flask\app.py", line 1796, in dispatch_request
    return self.ensure_sync(self.view_functions[rule.endpoint])(**view_args)
  File "C:\Users\UltAshes\Desktop\youxi-main2\app\main\view.py", line 31, in code
    redis_store.set("code", b, 60)
  File "C:\Users\UltAshes\AppData\Roaming\Python\Python310\site-packages\redis\commands\core.py", line 2313, in set
    return self.execute_command("SET", *pieces, **options)
  File "C:\Users\UltAshes\AppData\Roaming\Python\Python310\site-packages\redis\client.py", line 1266, in execute_command
    conn = self.connection or pool.get_connection(command_name, **options)
  File "C:\Users\UltAshes\AppData\Roaming\Python\Python310\site-packages\redis\connection.py", line 1457, in get_connection
    connection.connect()
  File "C:\Users\UltAshes\AppData\Roaming\Python\Python310\site-packages\redis\connection.py", line 705, in connect
    raise ConnectionError(self._error_message(e))
redis.exceptions.ConnectionError: Error 10061 connecting to 127.0.0.1:6379. 由于目标计算机积极拒绝，无法连接。.
2023-06-15 23:05:08,870 - app - ERROR - Exception on /information [GET]
Traceback (most recent call last):
  File "C:\Users\UltAshes\AppData\Local\Programs\Python\Python310\lib\site-packages\flask\app.py", line 2525, in wsgi_app
    response = self.full_dispatch_request()
  File "C:\Users\UltAshes\AppData\Local\Programs\Python\Python310\lib\site-packages\flask\app.py", line 1822, in full_dispatch_request
    rv = self.handle_user_exception(e)
  File "C:\Users\UltAshes\AppData\Local\Programs\Python\Python310\lib\site-packages\flask_cors\extension.py", line 165, in wrapped_function
    return cors_after_request(app.make_response(f(*args, **kwargs)))
  File "C:\Users\UltAshes\AppData\Local\Programs\Python\Python310\lib\site-packages\flask\app.py", line 1820, in full_dispatch_request
    rv = self.dispatch_request()
  File "C:\Users\UltAshes\AppData\Local\Programs\Python\Python310\lib\site-packages\flask\app.py", line 1796, in dispatch_request
    return self.ensure_sync(self.view_functions[rule.endpoint])(**view_args)
  File "C:\Users\UltAshes\Desktop\youxi-main2\app\main\utils.py", line 53, in decorate
    return func(dict(username=username, uid=uid, access=access))
  File "C:\Users\UltAshes\Desktop\youxi-main2\app\main\user.py", line 104, in information
    photo=jpg(search.photo))
  File "C:\Users\UltAshes\Desktop\youxi-main2\app\main\utils.py", line 19, in jpg
    return "https://7f1192d863.imdo.co" + x
TypeError: can only concatenate str (not "NoneType") to str
2023-06-15 23:05:16,043 - app - ERROR - Exception on /information [GET]
Traceback (most recent call last):
  File "C:\Users\UltAshes\AppData\Local\Programs\Python\Python310\lib\site-packages\flask\app.py", line 2525, in wsgi_app
    response = self.full_dispatch_request()
  File "C:\Users\UltAshes\AppData\Local\Programs\Python\Python310\lib\site-packages\flask\app.py", line 1822, in full_dispatch_request
    rv = self.handle_user_exception(e)
  File "C:\Users\UltAshes\AppData\Local\Programs\Python\Python310\lib\site-packages\flask_cors\extension.py", line 165, in wrapped_function
    return cors_after_request(app.make_response(f(*args, **kwargs)))
  File "C:\Users\UltAshes\AppData\Local\Programs\Python\Python310\lib\site-packages\flask\app.py", line 1820, in full_dispatch_request
    rv = self.dispatch_request()
  File "C:\Users\UltAshes\AppData\Local\Programs\Python\Python310\lib\site-packages\flask\app.py", line 1796, in dispatch_request
    return self.ensure_sync(self.view_functions[rule.endpoint])(**view_args)
  File "C:\Users\UltAshes\Desktop\youxi-main2\app\main\utils.py", line 53, in decorate
    return func(dict(username=username, uid=uid, access=access))
  File "C:\Users\UltAshes\Desktop\youxi-main2\app\main\user.py", line 104, in information
    photo=jpg(search.photo))
  File "C:\Users\UltAshes\Desktop\youxi-main2\app\main\utils.py", line 19, in jpg
    return "https://7f1192d863.imdo.co" + x
TypeError: can only concatenate str (not "NoneType") to str
2023-06-15 23:22:01,276 - app - ERROR - Exception on /login [POST]
Traceback (most recent call last):
  File "C:\Users\UltAshes\AppData\Local\Programs\Python\Python310\lib\site-packages\flask\app.py", line 2525, in wsgi_app
    response = self.full_dispatch_request()
  File "C:\Users\UltAshes\AppData\Local\Programs\Python\Python310\lib\site-packages\flask\app.py", line 1822, in full_dispatch_request
    rv = self.handle_user_exception(e)
  File "C:\Users\UltAshes\AppData\Local\Programs\Python\Python310\lib\site-packages\flask_cors\extension.py", line 165, in wrapped_function
    return cors_after_request(app.make_response(f(*args, **kwargs)))
  File "C:\Users\UltAshes\AppData\Local\Programs\Python\Python310\lib\site-packages\flask\app.py", line 1820, in full_dispatch_request
    rv = self.dispatch_request()
  File "C:\Users\UltAshes\AppData\Local\Programs\Python\Python310\lib\site-packages\flask\app.py", line 1796, in dispatch_request
    return self.ensure_sync(self.view_functions[rule.endpoint])(**view_args)
  File "C:\Users\UltAshes\Desktop\youxi-main2\app\main\user.py", line 51, in login
    code = get_json.get("code").lower()
AttributeError: 'NoneType' object has no attribute 'lower'
2023-06-15 23:22:29,097 - app - ERROR - Exception on /login [POST]
Traceback (most recent call last):
  File "C:\Users\UltAshes\AppData\Local\Programs\Python\Python310\lib\site-packages\flask\app.py", line 2525, in wsgi_app
    response = self.full_dispatch_request()
  File "C:\Users\UltAshes\AppData\Local\Programs\Python\Python310\lib\site-packages\flask\app.py", line 1822, in full_dispatch_request
    rv = self.handle_user_exception(e)
  File "C:\Users\UltAshes\AppData\Local\Programs\Python\Python310\lib\site-packages\flask_cors\extension.py", line 165, in wrapped_function
    return cors_after_request(app.make_response(f(*args, **kwargs)))
  File "C:\Users\UltAshes\AppData\Local\Programs\Python\Python310\lib\site-packages\flask\app.py", line 1820, in full_dispatch_request
    rv = self.dispatch_request()
  File "C:\Users\UltAshes\AppData\Local\Programs\Python\Python310\lib\site-packages\flask\app.py", line 1796, in dispatch_request
    return self.ensure_sync(self.view_functions[rule.endpoint])(**view_args)
  File "C:\Users\UltAshes\Desktop\youxi-main2\app\main\user.py", line 51, in login
    code = get_json.get("code").lower()
AttributeError: 'NoneType' object has no attribute 'lower'
2023-06-15 23:22:29,786 - app - ERROR - Exception on /login [POST]
Traceback (most recent call last):
  File "C:\Users\UltAshes\AppData\Local\Programs\Python\Python310\lib\site-packages\flask\app.py", line 2525, in wsgi_app
    response = self.full_dispatch_request()
  File "C:\Users\UltAshes\AppData\Local\Programs\Python\Python310\lib\site-packages\flask\app.py", line 1822, in full_dispatch_request
    rv = self.handle_user_exception(e)
  File "C:\Users\UltAshes\AppData\Local\Programs\Python\Python310\lib\site-packages\flask_cors\extension.py", line 165, in wrapped_function
    return cors_after_request(app.make_response(f(*args, **kwargs)))
  File "C:\Users\UltAshes\AppData\Local\Programs\Python\Python310\lib\site-packages\flask\app.py", line 1820, in full_dispatch_request
    rv = self.dispatch_request()
  File "C:\Users\UltAshes\AppData\Local\Programs\Python\Python310\lib\site-packages\flask\app.py", line 1796, in dispatch_request
    return self.ensure_sync(self.view_functions[rule.endpoint])(**view_args)
  File "C:\Users\UltAshes\Desktop\youxi-main2\app\main\user.py", line 51, in login
    code = get_json.get("code").lower()
AttributeError: 'NoneType' object has no attribute 'lower'
2023-06-15 23:38:54,902 - app - ERROR - Exception on /information [GET]
Traceback (most recent call last):
  File "C:\Users\UltAshes\AppData\Local\Programs\Python\Python310\lib\site-packages\flask\app.py", line 2525, in wsgi_app
    response = self.full_dispatch_request()
  File "C:\Users\UltAshes\AppData\Local\Programs\Python\Python310\lib\site-packages\flask\app.py", line 1822, in full_dispatch_request
    rv = self.handle_user_exception(e)
  File "C:\Users\UltAshes\AppData\Local\Programs\Python\Python310\lib\site-packages\flask_cors\extension.py", line 165, in wrapped_function
    return cors_after_request(app.make_response(f(*args, **kwargs)))
  File "C:\Users\UltAshes\AppData\Local\Programs\Python\Python310\lib\site-packages\flask\app.py", line 1820, in full_dispatch_request
    rv = self.dispatch_request()
  File "C:\Users\UltAshes\AppData\Local\Programs\Python\Python310\lib\site-packages\flask\app.py", line 1796, in dispatch_request
    return self.ensure_sync(self.view_functions[rule.endpoint])(**view_args)
  File "C:\Users\UltAshes\Desktop\youxi-main2\app\main\utils.py", line 53, in decorate
    return func(dict(username=username, uid=uid, access=access))
  File "C:\Users\UltAshes\Desktop\youxi-main2\app\main\user.py", line 104, in information
    photo=jpg(search.photo))
  File "C:\Users\UltAshes\Desktop\youxi-main2\app\main\utils.py", line 19, in jpg
    return "https://7f1192d863.imdo.co" + x
TypeError: can only concatenate str (not "NoneType") to str
2023-06-15 23:38:59,305 - app - ERROR - Exception on /information [GET]
Traceback (most recent call last):
  File "C:\Users\UltAshes\AppData\Local\Programs\Python\Python310\lib\site-packages\flask\app.py", line 2525, in wsgi_app
    response = self.full_dispatch_request()
  File "C:\Users\UltAshes\AppData\Local\Programs\Python\Python310\lib\site-packages\flask\app.py", line 1822, in full_dispatch_request
    rv = self.handle_user_exception(e)
  File "C:\Users\UltAshes\AppData\Local\Programs\Python\Python310\lib\site-packages\flask_cors\extension.py", line 165, in wrapped_function
    return cors_after_request(app.make_response(f(*args, **kwargs)))
  File "C:\Users\UltAshes\AppData\Local\Programs\Python\Python310\lib\site-packages\flask\app.py", line 1820, in full_dispatch_request
    rv = self.dispatch_request()
  File "C:\Users\UltAshes\AppData\Local\Programs\Python\Python310\lib\site-packages\flask\app.py", line 1796, in dispatch_request
    return self.ensure_sync(self.view_functions[rule.endpoint])(**view_args)
  File "C:\Users\UltAshes\Desktop\youxi-main2\app\main\utils.py", line 53, in decorate
    return func(dict(username=username, uid=uid, access=access))
  File "C:\Users\UltAshes\Desktop\youxi-main2\app\main\user.py", line 104, in information
    photo=jpg(search.photo))
  File "C:\Users\UltAshes\Desktop\youxi-main2\app\main\utils.py", line 19, in jpg
    return "https://7f1192d863.imdo.co" + x
TypeError: can only concatenate str (not "NoneType") to str
2023-06-15 23:39:03,260 - app - ERROR - Exception on /information [GET]
Traceback (most recent call last):
  File "C:\Users\UltAshes\AppData\Local\Programs\Python\Python310\lib\site-packages\flask\app.py", line 2525, in wsgi_app
    response = self.full_dispatch_request()
  File "C:\Users\UltAshes\AppData\Local\Programs\Python\Python310\lib\site-packages\flask\app.py", line 1822, in full_dispatch_request
    rv = self.handle_user_exception(e)
  File "C:\Users\UltAshes\AppData\Local\Programs\Python\Python310\lib\site-packages\flask_cors\extension.py", line 165, in wrapped_function
    return cors_after_request(app.make_response(f(*args, **kwargs)))
  File "C:\Users\UltAshes\AppData\Local\Programs\Python\Python310\lib\site-packages\flask\app.py", line 1820, in full_dispatch_request
    rv = self.dispatch_request()
  File "C:\Users\UltAshes\AppData\Local\Programs\Python\Python310\lib\site-packages\flask\app.py", line 1796, in dispatch_request
    return self.ensure_sync(self.view_functions[rule.endpoint])(**view_args)
  File "C:\Users\UltAshes\Desktop\youxi-main2\app\main\utils.py", line 53, in decorate
    return func(dict(username=username, uid=uid, access=access))
  File "C:\Users\UltAshes\Desktop\youxi-main2\app\main\user.py", line 104, in information
    photo=jpg(search.photo))
  File "C:\Users\UltAshes\Desktop\youxi-main2\app\main\utils.py", line 19, in jpg
    return "https://7f1192d863.imdo.co" + x
TypeError: can only concatenate str (not "NoneType") to str
2023-06-15 23:39:58,799 - app - ERROR - Exception on /information [GET]
Traceback (most recent call last):
  File "C:\Users\UltAshes\AppData\Local\Programs\Python\Python310\lib\site-packages\flask\app.py", line 2525, in wsgi_app
    response = self.full_dispatch_request()
  File "C:\Users\UltAshes\AppData\Local\Programs\Python\Python310\lib\site-packages\flask\app.py", line 1822, in full_dispatch_request
    rv = self.handle_user_exception(e)
  File "C:\Users\UltAshes\AppData\Local\Programs\Python\Python310\lib\site-packages\flask_cors\extension.py", line 165, in wrapped_function
    return cors_after_request(app.make_response(f(*args, **kwargs)))
  File "C:\Users\UltAshes\AppData\Local\Programs\Python\Python310\lib\site-packages\flask\app.py", line 1820, in full_dispatch_request
    rv = self.dispatch_request()
  File "C:\Users\UltAshes\AppData\Local\Programs\Python\Python310\lib\site-packages\flask\app.py", line 1796, in dispatch_request
    return self.ensure_sync(self.view_functions[rule.endpoint])(**view_args)
  File "C:\Users\UltAshes\Desktop\youxi-main2\app\main\utils.py", line 53, in decorate
    return func(dict(username=username, uid=uid, access=access))
  File "C:\Users\UltAshes\Desktop\youxi-main2\app\main\user.py", line 104, in information
    photo=jpg(search.photo))
  File "C:\Users\UltAshes\Desktop\youxi-main2\app\main\utils.py", line 19, in jpg
    return "https://7f1192d863.imdo.co" + x
TypeError: can only concatenate str (not "NoneType") to str
2023-06-15 23:40:01,289 - app - ERROR - Exception on /information [GET]
Traceback (most recent call last):
  File "C:\Users\UltAshes\AppData\Local\Programs\Python\Python310\lib\site-packages\flask\app.py", line 2525, in wsgi_app
    response = self.full_dispatch_request()
  File "C:\Users\UltAshes\AppData\Local\Programs\Python\Python310\lib\site-packages\flask\app.py", line 1822, in full_dispatch_request
    rv = self.handle_user_exception(e)
  File "C:\Users\UltAshes\AppData\Local\Programs\Python\Python310\lib\site-packages\flask_cors\extension.py", line 165, in wrapped_function
    return cors_after_request(app.make_response(f(*args, **kwargs)))
  File "C:\Users\UltAshes\AppData\Local\Programs\Python\Python310\lib\site-packages\flask\app.py", line 1820, in full_dispatch_request
    rv = self.dispatch_request()
  File "C:\Users\UltAshes\AppData\Local\Programs\Python\Python310\lib\site-packages\flask\app.py", line 1796, in dispatch_request
    return self.ensure_sync(self.view_functions[rule.endpoint])(**view_args)
  File "C:\Users\UltAshes\Desktop\youxi-main2\app\main\utils.py", line 53, in decorate
    return func(dict(username=username, uid=uid, access=access))
  File "C:\Users\UltAshes\Desktop\youxi-main2\app\main\user.py", line 104, in information
    photo=jpg(search.photo))
  File "C:\Users\UltAshes\Desktop\youxi-main2\app\main\utils.py", line 19, in jpg
    return "https://7f1192d863.imdo.co" + x
TypeError: can only concatenate str (not "NoneType") to str
2023-06-15 23:42:34,645 - app - ERROR - Exception on /information [GET]
Traceback (most recent call last):
  File "C:\Users\UltAshes\AppData\Local\Programs\Python\Python310\lib\site-packages\flask\app.py", line 2525, in wsgi_app
    response = self.full_dispatch_request()
  File "C:\Users\UltAshes\AppData\Local\Programs\Python\Python310\lib\site-packages\flask\app.py", line 1822, in full_dispatch_request
    rv = self.handle_user_exception(e)
  File "C:\Users\UltAshes\AppData\Local\Programs\Python\Python310\lib\site-packages\flask_cors\extension.py", line 165, in wrapped_function
    return cors_after_request(app.make_response(f(*args, **kwargs)))
  File "C:\Users\UltAshes\AppData\Local\Programs\Python\Python310\lib\site-packages\flask\app.py", line 1820, in full_dispatch_request
    rv = self.dispatch_request()
  File "C:\Users\UltAshes\AppData\Local\Programs\Python\Python310\lib\site-packages\flask\app.py", line 1796, in dispatch_request
    return self.ensure_sync(self.view_functions[rule.endpoint])(**view_args)
  File "C:\Users\UltAshes\Desktop\youxi-main2\app\main\utils.py", line 53, in decorate
    return func(dict(username=username, uid=uid, access=access))
  File "C:\Users\UltAshes\Desktop\youxi-main2\app\main\user.py", line 104, in information
    photo=jpg(search.photo))
  File "C:\Users\UltAshes\Desktop\youxi-main2\app\main\utils.py", line 19, in jpg
    return "https://7f1192d863.imdo.co" + x
TypeError: can only concatenate str (not "NoneType") to str
2023-06-15 23:42:37,620 - app - ERROR - Exception on /information [GET]
Traceback (most recent call last):
  File "C:\Users\UltAshes\AppData\Local\Programs\Python\Python310\lib\site-packages\flask\app.py", line 2525, in wsgi_app
    response = self.full_dispatch_request()
  File "C:\Users\UltAshes\AppData\Local\Programs\Python\Python310\lib\site-packages\flask\app.py", line 1822, in full_dispatch_request
    rv = self.handle_user_exception(e)
  File "C:\Users\UltAshes\AppData\Local\Programs\Python\Python310\lib\site-packages\flask_cors\extension.py", line 165, in wrapped_function
    return cors_after_request(app.make_response(f(*args, **kwargs)))
  File "C:\Users\UltAshes\AppData\Local\Programs\Python\Python310\lib\site-packages\flask\app.py", line 1820, in full_dispatch_request
    rv = self.dispatch_request()
  File "C:\Users\UltAshes\AppData\Local\Programs\Python\Python310\lib\site-packages\flask\app.py", line 1796, in dispatch_request
    return self.ensure_sync(self.view_functions[rule.endpoint])(**view_args)
  File "C:\Users\UltAshes\Desktop\youxi-main2\app\main\utils.py", line 53, in decorate
    return func(dict(username=username, uid=uid, access=access))
  File "C:\Users\UltAshes\Desktop\youxi-main2\app\main\user.py", line 104, in information
    photo=jpg(search.photo))
  File "C:\Users\UltAshes\Desktop\youxi-main2\app\main\utils.py", line 19, in jpg
    return "https://7f1192d863.imdo.co" + x
TypeError: can only concatenate str (not "NoneType") to str
2023-06-15 23:42:46,095 - app - ERROR - Exception on /information [GET]
Traceback (most recent call last):
  File "C:\Users\UltAshes\AppData\Local\Programs\Python\Python310\lib\site-packages\flask\app.py", line 2525, in wsgi_app
    response = self.full_dispatch_request()
  File "C:\Users\UltAshes\AppData\Local\Programs\Python\Python310\lib\site-packages\flask\app.py", line 1822, in full_dispatch_request
    rv = self.handle_user_exception(e)
  File "C:\Users\UltAshes\AppData\Local\Programs\Python\Python310\lib\site-packages\flask_cors\extension.py", line 165, in wrapped_function
    return cors_after_request(app.make_response(f(*args, **kwargs)))
  File "C:\Users\UltAshes\AppData\Local\Programs\Python\Python310\lib\site-packages\flask\app.py", line 1820, in full_dispatch_request
    rv = self.dispatch_request()
  File "C:\Users\UltAshes\AppData\Local\Programs\Python\Python310\lib\site-packages\flask\app.py", line 1796, in dispatch_request
    return self.ensure_sync(self.view_functions[rule.endpoint])(**view_args)
  File "C:\Users\UltAshes\Desktop\youxi-main2\app\main\utils.py", line 53, in decorate
    return func(dict(username=username, uid=uid, access=access))
  File "C:\Users\UltAshes\Desktop\youxi-main2\app\main\user.py", line 104, in information
    photo=jpg(search.photo))
  File "C:\Users\UltAshes\Desktop\youxi-main2\app\main\utils.py", line 19, in jpg
    return "https://7f1192d863.imdo.co" + x
TypeError: can only concatenate str (not "NoneType") to str
2023-06-15 23:42:51,914 - app - ERROR - Exception on /information [GET]
Traceback (most recent call last):
  File "C:\Users\UltAshes\AppData\Local\Programs\Python\Python310\lib\site-packages\flask\app.py", line 2525, in wsgi_app
    response = self.full_dispatch_request()
  File "C:\Users\UltAshes\AppData\Local\Programs\Python\Python310\lib\site-packages\flask\app.py", line 1822, in full_dispatch_request
    rv = self.handle_user_exception(e)
  File "C:\Users\UltAshes\AppData\Local\Programs\Python\Python310\lib\site-packages\flask_cors\extension.py", line 165, in wrapped_function
    return cors_after_request(app.make_response(f(*args, **kwargs)))
  File "C:\Users\UltAshes\AppData\Local\Programs\Python\Python310\lib\site-packages\flask\app.py", line 1820, in full_dispatch_request
    rv = self.dispatch_request()
  File "C:\Users\UltAshes\AppData\Local\Programs\Python\Python310\lib\site-packages\flask\app.py", line 1796, in dispatch_request
    return self.ensure_sync(self.view_functions[rule.endpoint])(**view_args)
  File "C:\Users\UltAshes\Desktop\youxi-main2\app\main\utils.py", line 53, in decorate
    return func(dict(username=username, uid=uid, access=access))
  File "C:\Users\UltAshes\Desktop\youxi-main2\app\main\user.py", line 104, in information
    photo=jpg(search.photo))
  File "C:\Users\UltAshes\Desktop\youxi-main2\app\main\utils.py", line 19, in jpg
    return "https://7f1192d863.imdo.co" + x
TypeError: can only concatenate str (not "NoneType") to str
2023-06-15 23:42:55,664 - app - ERROR - Exception on /information [GET]
Traceback (most recent call last):
  File "C:\Users\UltAshes\AppData\Local\Programs\Python\Python310\lib\site-packages\flask\app.py", line 2525, in wsgi_app
    response = self.full_dispatch_request()
  File "C:\Users\UltAshes\AppData\Local\Programs\Python\Python310\lib\site-packages\flask\app.py", line 1822, in full_dispatch_request
    rv = self.handle_user_exception(e)
  File "C:\Users\UltAshes\AppData\Local\Programs\Python\Python310\lib\site-packages\flask_cors\extension.py", line 165, in wrapped_function
    return cors_after_request(app.make_response(f(*args, **kwargs)))
  File "C:\Users\UltAshes\AppData\Local\Programs\Python\Python310\lib\site-packages\flask\app.py", line 1820, in full_dispatch_request
    rv = self.dispatch_request()
  File "C:\Users\UltAshes\AppData\Local\Programs\Python\Python310\lib\site-packages\flask\app.py", line 1796, in dispatch_request
    return self.ensure_sync(self.view_functions[rule.endpoint])(**view_args)
  File "C:\Users\UltAshes\Desktop\youxi-main2\app\main\utils.py", line 53, in decorate
    return func(dict(username=username, uid=uid, access=access))
  File "C:\Users\UltAshes\Desktop\youxi-main2\app\main\user.py", line 104, in information
    photo=jpg(search.photo))
  File "C:\Users\UltAshes\Desktop\youxi-main2\app\main\utils.py", line 19, in jpg
    return "https://7f1192d863.imdo.co" + x
TypeError: can only concatenate str (not "NoneType") to str
2023-06-15 23:43:39,182 - app - ERROR - Exception on /information [GET]
Traceback (most recent call last):
  File "C:\Users\UltAshes\AppData\Local\Programs\Python\Python310\lib\site-packages\flask\app.py", line 2525, in wsgi_app
    response = self.full_dispatch_request()
  File "C:\Users\UltAshes\AppData\Local\Programs\Python\Python310\lib\site-packages\flask\app.py", line 1822, in full_dispatch_request
    rv = self.handle_user_exception(e)
  File "C:\Users\UltAshes\AppData\Local\Programs\Python\Python310\lib\site-packages\flask_cors\extension.py", line 165, in wrapped_function
    return cors_after_request(app.make_response(f(*args, **kwargs)))
  File "C:\Users\UltAshes\AppData\Local\Programs\Python\Python310\lib\site-packages\flask\app.py", line 1820, in full_dispatch_request
    rv = self.dispatch_request()
  File "C:\Users\UltAshes\AppData\Local\Programs\Python\Python310\lib\site-packages\flask\app.py", line 1796, in dispatch_request
    return self.ensure_sync(self.view_functions[rule.endpoint])(**view_args)
  File "C:\Users\UltAshes\Desktop\youxi-main2\app\main\utils.py", line 53, in decorate
    return func(dict(username=username, uid=uid, access=access))
  File "C:\Users\UltAshes\Desktop\youxi-main2\app\main\user.py", line 104, in information
    photo=jpg(search.photo))
  File "C:\Users\UltAshes\Desktop\youxi-main2\app\main\utils.py", line 19, in jpg
    return "https://7f1192d863.imdo.co" + x
TypeError: can only concatenate str (not "NoneType") to str
2023-06-15 23:43:42,374 - app - ERROR - Exception on /information [GET]
Traceback (most recent call last):
  File "C:\Users\UltAshes\AppData\Local\Programs\Python\Python310\lib\site-packages\flask\app.py", line 2525, in wsgi_app
    response = self.full_dispatch_request()
  File "C:\Users\UltAshes\AppData\Local\Programs\Python\Python310\lib\site-packages\flask\app.py", line 1822, in full_dispatch_request
    rv = self.handle_user_exception(e)
  File "C:\Users\UltAshes\AppData\Local\Programs\Python\Python310\lib\site-packages\flask_cors\extension.py", line 165, in wrapped_function
    return cors_after_request(app.make_response(f(*args, **kwargs)))
  File "C:\Users\UltAshes\AppData\Local\Programs\Python\Python310\lib\site-packages\flask\app.py", line 1820, in full_dispatch_request
    rv = self.dispatch_request()
  File "C:\Users\UltAshes\AppData\Local\Programs\Python\Python310\lib\site-packages\flask\app.py", line 1796, in dispatch_request
    return self.ensure_sync(self.view_functions[rule.endpoint])(**view_args)
  File "C:\Users\UltAshes\Desktop\youxi-main2\app\main\utils.py", line 53, in decorate
    return func(dict(username=username, uid=uid, access=access))
  File "C:\Users\UltAshes\Desktop\youxi-main2\app\main\user.py", line 104, in information
    photo=jpg(search.photo))
  File "C:\Users\UltAshes\Desktop\youxi-main2\app\main\utils.py", line 19, in jpg
    return "https://7f1192d863.imdo.co" + x
TypeError: can only concatenate str (not "NoneType") to str
2023-06-15 23:43:54,511 - app - ERROR - Exception on /information [GET]
Traceback (most recent call last):
  File "C:\Users\UltAshes\AppData\Local\Programs\Python\Python310\lib\site-packages\flask\app.py", line 2525, in wsgi_app
    response = self.full_dispatch_request()
  File "C:\Users\UltAshes\AppData\Local\Programs\Python\Python310\lib\site-packages\flask\app.py", line 1822, in full_dispatch_request
    rv = self.handle_user_exception(e)
  File "C:\Users\UltAshes\AppData\Local\Programs\Python\Python310\lib\site-packages\flask_cors\extension.py", line 165, in wrapped_function
    return cors_after_request(app.make_response(f(*args, **kwargs)))
  File "C:\Users\UltAshes\AppData\Local\Programs\Python\Python310\lib\site-packages\flask\app.py", line 1820, in full_dispatch_request
    rv = self.dispatch_request()
  File "C:\Users\UltAshes\AppData\Local\Programs\Python\Python310\lib\site-packages\flask\app.py", line 1796, in dispatch_request
    return self.ensure_sync(self.view_functions[rule.endpoint])(**view_args)
  File "C:\Users\UltAshes\Desktop\youxi-main2\app\main\utils.py", line 53, in decorate
    return func(dict(username=username, uid=uid, access=access))
  File "C:\Users\UltAshes\Desktop\youxi-main2\app\main\user.py", line 104, in information
    photo=jpg(search.photo))
  File "C:\Users\UltAshes\Desktop\youxi-main2\app\main\utils.py", line 19, in jpg
    return "https://7f1192d863.imdo.co" + x
TypeError: can only concatenate str (not "NoneType") to str
2023-06-16 15:28:53,952 - app - ERROR - Exception on /information [GET]
Traceback (most recent call last):
  File "C:\Users\asus\AppData\Roaming\Python\Python310\site-packages\flask\app.py", line 2525, in wsgi_app
    response = self.full_dispatch_request()
  File "C:\Users\asus\AppData\Roaming\Python\Python310\site-packages\flask\app.py", line 1822, in full_dispatch_request
    rv = self.handle_user_exception(e)
  File "D:\Users\asus\Desktop\youxi\venv\lib\site-packages\flask_cors\extension.py", line 165, in wrapped_function
    return cors_after_request(app.make_response(f(*args, **kwargs)))
  File "C:\Users\asus\AppData\Roaming\Python\Python310\site-packages\flask\app.py", line 1820, in full_dispatch_request
    rv = self.dispatch_request()
  File "C:\Users\asus\AppData\Roaming\Python\Python310\site-packages\flask\app.py", line 1796, in dispatch_request
    return self.ensure_sync(self.view_functions[rule.endpoint])(**view_args)
  File "D:\Users\asus\Desktop\youxi\app\main\utils.py", line 53, in decorate
    return func(dict(username=username, uid=uid, access=access))
  File "D:\Users\asus\Desktop\youxi\app\main\user.py", line 104, in information
    photo=jpg(search.photo))
  File "D:\Users\asus\Desktop\youxi\app\main\utils.py", line 19, in jpg
    return "https://7f1192d863.imdo.co" + x
TypeError: can only concatenate str (not "NoneType") to str
2023-06-16 15:28:57,798 - app - ERROR - Exception on /information [GET]
Traceback (most recent call last):
  File "C:\Users\asus\AppData\Roaming\Python\Python310\site-packages\flask\app.py", line 2525, in wsgi_app
    response = self.full_dispatch_request()
  File "C:\Users\asus\AppData\Roaming\Python\Python310\site-packages\flask\app.py", line 1822, in full_dispatch_request
    rv = self.handle_user_exception(e)
  File "D:\Users\asus\Desktop\youxi\venv\lib\site-packages\flask_cors\extension.py", line 165, in wrapped_function
    return cors_after_request(app.make_response(f(*args, **kwargs)))
  File "C:\Users\asus\AppData\Roaming\Python\Python310\site-packages\flask\app.py", line 1820, in full_dispatch_request
    rv = self.dispatch_request()
  File "C:\Users\asus\AppData\Roaming\Python\Python310\site-packages\flask\app.py", line 1796, in dispatch_request
    return self.ensure_sync(self.view_functions[rule.endpoint])(**view_args)
  File "D:\Users\asus\Desktop\youxi\app\main\utils.py", line 53, in decorate
    return func(dict(username=username, uid=uid, access=access))
  File "D:\Users\asus\Desktop\youxi\app\main\user.py", line 104, in information
    photo=jpg(search.photo))
  File "D:\Users\asus\Desktop\youxi\app\main\utils.py", line 19, in jpg
    return "https://7f1192d863.imdo.co" + x
TypeError: can only concatenate str (not "NoneType") to str
2023-06-16 15:29:58,041 - app - ERROR - Exception on /information [GET]
Traceback (most recent call last):
  File "C:\Users\asus\AppData\Roaming\Python\Python310\site-packages\flask\app.py", line 2525, in wsgi_app
    response = self.full_dispatch_request()
  File "C:\Users\asus\AppData\Roaming\Python\Python310\site-packages\flask\app.py", line 1822, in full_dispatch_request
    rv = self.handle_user_exception(e)
  File "D:\Users\asus\Desktop\youxi\venv\lib\site-packages\flask_cors\extension.py", line 165, in wrapped_function
    return cors_after_request(app.make_response(f(*args, **kwargs)))
  File "C:\Users\asus\AppData\Roaming\Python\Python310\site-packages\flask\app.py", line 1820, in full_dispatch_request
    rv = self.dispatch_request()
  File "C:\Users\asus\AppData\Roaming\Python\Python310\site-packages\flask\app.py", line 1796, in dispatch_request
    return self.ensure_sync(self.view_functions[rule.endpoint])(**view_args)
  File "D:\Users\asus\Desktop\youxi\app\main\utils.py", line 53, in decorate
    return func(dict(username=username, uid=uid, access=access))
  File "D:\Users\asus\Desktop\youxi\app\main\user.py", line 104, in information
    photo=jpg(search.photo))
  File "D:\Users\asus\Desktop\youxi\app\main\utils.py", line 19, in jpg
    return "https://7f1192d863.imdo.co" + x
TypeError: can only concatenate str (not "NoneType") to str
2023-06-16 15:30:11,234 - app - ERROR - Exception on /information [GET]
Traceback (most recent call last):
  File "C:\Users\asus\AppData\Roaming\Python\Python310\site-packages\flask\app.py", line 2525, in wsgi_app
    response = self.full_dispatch_request()
  File "C:\Users\asus\AppData\Roaming\Python\Python310\site-packages\flask\app.py", line 1822, in full_dispatch_request
    rv = self.handle_user_exception(e)
  File "D:\Users\asus\Desktop\youxi\venv\lib\site-packages\flask_cors\extension.py", line 165, in wrapped_function
    return cors_after_request(app.make_response(f(*args, **kwargs)))
  File "C:\Users\asus\AppData\Roaming\Python\Python310\site-packages\flask\app.py", line 1820, in full_dispatch_request
    rv = self.dispatch_request()
  File "C:\Users\asus\AppData\Roaming\Python\Python310\site-packages\flask\app.py", line 1796, in dispatch_request
    return self.ensure_sync(self.view_functions[rule.endpoint])(**view_args)
  File "D:\Users\asus\Desktop\youxi\app\main\utils.py", line 53, in decorate
    return func(dict(username=username, uid=uid, access=access))
  File "D:\Users\asus\Desktop\youxi\app\main\user.py", line 104, in information
    photo=jpg(search.photo))
  File "D:\Users\asus\Desktop\youxi\app\main\utils.py", line 19, in jpg
    return "https://7f1192d863.imdo.co" + x
TypeError: can only concatenate str (not "NoneType") to str
2023-06-16 15:32:13,359 - app - ERROR - Exception on /information [GET]
Traceback (most recent call last):
  File "C:\Users\asus\AppData\Roaming\Python\Python310\site-packages\flask\app.py", line 2525, in wsgi_app
    response = self.full_dispatch_request()
  File "C:\Users\asus\AppData\Roaming\Python\Python310\site-packages\flask\app.py", line 1822, in full_dispatch_request
    rv = self.handle_user_exception(e)
  File "D:\Users\asus\Desktop\youxi\venv\lib\site-packages\flask_cors\extension.py", line 165, in wrapped_function
    return cors_after_request(app.make_response(f(*args, **kwargs)))
  File "C:\Users\asus\AppData\Roaming\Python\Python310\site-packages\flask\app.py", line 1820, in full_dispatch_request
    rv = self.dispatch_request()
  File "C:\Users\asus\AppData\Roaming\Python\Python310\site-packages\flask\app.py", line 1796, in dispatch_request
    return self.ensure_sync(self.view_functions[rule.endpoint])(**view_args)
  File "D:\Users\asus\Desktop\youxi\app\main\utils.py", line 53, in decorate
    return func(dict(username=username, uid=uid, access=access))
  File "D:\Users\asus\Desktop\youxi\app\main\user.py", line 104, in information
    photo=jpg(search.photo))
  File "D:\Users\asus\Desktop\youxi\app\main\utils.py", line 19, in jpg
    return "https://7f1192d863.imdo.co" + x
TypeError: can only concatenate str (not "NoneType") to str
2023-06-16 15:32:23,142 - app - ERROR - Exception on /information [GET]
Traceback (most recent call last):
  File "C:\Users\asus\AppData\Roaming\Python\Python310\site-packages\flask\app.py", line 2525, in wsgi_app
    response = self.full_dispatch_request()
  File "C:\Users\asus\AppData\Roaming\Python\Python310\site-packages\flask\app.py", line 1822, in full_dispatch_request
    rv = self.handle_user_exception(e)
  File "D:\Users\asus\Desktop\youxi\venv\lib\site-packages\flask_cors\extension.py", line 165, in wrapped_function
    return cors_after_request(app.make_response(f(*args, **kwargs)))
  File "C:\Users\asus\AppData\Roaming\Python\Python310\site-packages\flask\app.py", line 1820, in full_dispatch_request
    rv = self.dispatch_request()
  File "C:\Users\asus\AppData\Roaming\Python\Python310\site-packages\flask\app.py", line 1796, in dispatch_request
    return self.ensure_sync(self.view_functions[rule.endpoint])(**view_args)
  File "D:\Users\asus\Desktop\youxi\app\main\utils.py", line 53, in decorate
    return func(dict(username=username, uid=uid, access=access))
  File "D:\Users\asus\Desktop\youxi\app\main\user.py", line 104, in information
    photo=jpg(search.photo))
  File "D:\Users\asus\Desktop\youxi\app\main\utils.py", line 19, in jpg
    return "https://7f1192d863.imdo.co" + x
TypeError: can only concatenate str (not "NoneType") to str
2023-06-16 15:32:25,175 - app - ERROR - Exception on /information [GET]
Traceback (most recent call last):
  File "C:\Users\asus\AppData\Roaming\Python\Python310\site-packages\flask\app.py", line 2525, in wsgi_app
    response = self.full_dispatch_request()
  File "C:\Users\asus\AppData\Roaming\Python\Python310\site-packages\flask\app.py", line 1822, in full_dispatch_request
    rv = self.handle_user_exception(e)
  File "D:\Users\asus\Desktop\youxi\venv\lib\site-packages\flask_cors\extension.py", line 165, in wrapped_function
    return cors_after_request(app.make_response(f(*args, **kwargs)))
  File "C:\Users\asus\AppData\Roaming\Python\Python310\site-packages\flask\app.py", line 1820, in full_dispatch_request
    rv = self.dispatch_request()
  File "C:\Users\asus\AppData\Roaming\Python\Python310\site-packages\flask\app.py", line 1796, in dispatch_request
    return self.ensure_sync(self.view_functions[rule.endpoint])(**view_args)
  File "D:\Users\asus\Desktop\youxi\app\main\utils.py", line 53, in decorate
    return func(dict(username=username, uid=uid, access=access))
  File "D:\Users\asus\Desktop\youxi\app\main\user.py", line 104, in information
    photo=jpg(search.photo))
  File "D:\Users\asus\Desktop\youxi\app\main\utils.py", line 19, in jpg
    return "https://7f1192d863.imdo.co" + x
TypeError: can only concatenate str (not "NoneType") to str
2023-06-16 15:34:10,018 - app - ERROR - Exception on /information [GET]
Traceback (most recent call last):
  File "C:\Users\asus\AppData\Roaming\Python\Python310\site-packages\flask\app.py", line 2525, in wsgi_app
    response = self.full_dispatch_request()
  File "C:\Users\asus\AppData\Roaming\Python\Python310\site-packages\flask\app.py", line 1822, in full_dispatch_request
    rv = self.handle_user_exception(e)
  File "D:\Users\asus\Desktop\youxi\venv\lib\site-packages\flask_cors\extension.py", line 165, in wrapped_function
    return cors_after_request(app.make_response(f(*args, **kwargs)))
  File "C:\Users\asus\AppData\Roaming\Python\Python310\site-packages\flask\app.py", line 1820, in full_dispatch_request
    rv = self.dispatch_request()
  File "C:\Users\asus\AppData\Roaming\Python\Python310\site-packages\flask\app.py", line 1796, in dispatch_request
    return self.ensure_sync(self.view_functions[rule.endpoint])(**view_args)
  File "D:\Users\asus\Desktop\youxi\app\main\utils.py", line 53, in decorate
    return func(dict(username=username, uid=uid, access=access))
  File "D:\Users\asus\Desktop\youxi\app\main\user.py", line 105, in information
    photo=jpg(search.photo))
  File "D:\Users\asus\Desktop\youxi\app\main\utils.py", line 19, in jpg
    return "https://7f1192d863.imdo.co" + x
TypeError: can only concatenate str (not "NoneType") to str
2023-06-16 15:34:10,909 - app - ERROR - Exception on /information [GET]
Traceback (most recent call last):
  File "C:\Users\asus\AppData\Roaming\Python\Python310\site-packages\flask\app.py", line 2525, in wsgi_app
    response = self.full_dispatch_request()
  File "C:\Users\asus\AppData\Roaming\Python\Python310\site-packages\flask\app.py", line 1822, in full_dispatch_request
    rv = self.handle_user_exception(e)
  File "D:\Users\asus\Desktop\youxi\venv\lib\site-packages\flask_cors\extension.py", line 165, in wrapped_function
    return cors_after_request(app.make_response(f(*args, **kwargs)))
  File "C:\Users\asus\AppData\Roaming\Python\Python310\site-packages\flask\app.py", line 1820, in full_dispatch_request
    rv = self.dispatch_request()
  File "C:\Users\asus\AppData\Roaming\Python\Python310\site-packages\flask\app.py", line 1796, in dispatch_request
    return self.ensure_sync(self.view_functions[rule.endpoint])(**view_args)
  File "D:\Users\asus\Desktop\youxi\app\main\utils.py", line 53, in decorate
    return func(dict(username=username, uid=uid, access=access))
  File "D:\Users\asus\Desktop\youxi\app\main\user.py", line 105, in information
    photo=jpg(search.photo))
  File "D:\Users\asus\Desktop\youxi\app\main\utils.py", line 19, in jpg
    return "https://7f1192d863.imdo.co" + x
TypeError: can only concatenate str (not "NoneType") to str
2023-06-16 15:34:36,715 - app - ERROR - Exception on /information [GET]
Traceback (most recent call last):
  File "C:\Users\asus\AppData\Roaming\Python\Python310\site-packages\flask\app.py", line 2525, in wsgi_app
    response = self.full_dispatch_request()
  File "C:\Users\asus\AppData\Roaming\Python\Python310\site-packages\flask\app.py", line 1822, in full_dispatch_request
    rv = self.handle_user_exception(e)
  File "D:\Users\asus\Desktop\youxi\venv\lib\site-packages\flask_cors\extension.py", line 165, in wrapped_function
    return cors_after_request(app.make_response(f(*args, **kwargs)))
  File "C:\Users\asus\AppData\Roaming\Python\Python310\site-packages\flask\app.py", line 1820, in full_dispatch_request
    rv = self.dispatch_request()
  File "C:\Users\asus\AppData\Roaming\Python\Python310\site-packages\flask\app.py", line 1796, in dispatch_request
    return self.ensure_sync(self.view_functions[rule.endpoint])(**view_args)
  File "D:\Users\asus\Desktop\youxi\app\main\utils.py", line 53, in decorate
    return func(dict(username=username, uid=uid, access=access))
  File "D:\Users\asus\Desktop\youxi\app\main\user.py", line 105, in information
    photo=jpg(search.photo))
  File "D:\Users\asus\Desktop\youxi\app\main\utils.py", line 19, in jpg
    return "https://7f1192d863.imdo.co" + x
TypeError: can only concatenate str (not "NoneType") to str
2023-06-16 15:34:38,979 - app - ERROR - Exception on /information [GET]
Traceback (most recent call last):
  File "C:\Users\asus\AppData\Roaming\Python\Python310\site-packages\flask\app.py", line 2525, in wsgi_app
    response = self.full_dispatch_request()
  File "C:\Users\asus\AppData\Roaming\Python\Python310\site-packages\flask\app.py", line 1822, in full_dispatch_request
    rv = self.handle_user_exception(e)
  File "D:\Users\asus\Desktop\youxi\venv\lib\site-packages\flask_cors\extension.py", line 165, in wrapped_function
    return cors_after_request(app.make_response(f(*args, **kwargs)))
  File "C:\Users\asus\AppData\Roaming\Python\Python310\site-packages\flask\app.py", line 1820, in full_dispatch_request
    rv = self.dispatch_request()
  File "C:\Users\asus\AppData\Roaming\Python\Python310\site-packages\flask\app.py", line 1796, in dispatch_request
    return self.ensure_sync(self.view_functions[rule.endpoint])(**view_args)
  File "D:\Users\asus\Desktop\youxi\app\main\utils.py", line 53, in decorate
    return func(dict(username=username, uid=uid, access=access))
  File "D:\Users\asus\Desktop\youxi\app\main\user.py", line 105, in information
    photo=jpg(search.photo))
  File "D:\Users\asus\Desktop\youxi\app\main\utils.py", line 19, in jpg
    return "https://7f1192d863.imdo.co" + x
TypeError: can only concatenate str (not "NoneType") to str
2023-06-16 15:34:40,365 - app - ERROR - Exception on /information [GET]
Traceback (most recent call last):
  File "C:\Users\asus\AppData\Roaming\Python\Python310\site-packages\flask\app.py", line 2525, in wsgi_app
    response = self.full_dispatch_request()
  File "C:\Users\asus\AppData\Roaming\Python\Python310\site-packages\flask\app.py", line 1822, in full_dispatch_request
    rv = self.handle_user_exception(e)
  File "D:\Users\asus\Desktop\youxi\venv\lib\site-packages\flask_cors\extension.py", line 165, in wrapped_function
    return cors_after_request(app.make_response(f(*args, **kwargs)))
  File "C:\Users\asus\AppData\Roaming\Python\Python310\site-packages\flask\app.py", line 1820, in full_dispatch_request
    rv = self.dispatch_request()
  File "C:\Users\asus\AppData\Roaming\Python\Python310\site-packages\flask\app.py", line 1796, in dispatch_request
    return self.ensure_sync(self.view_functions[rule.endpoint])(**view_args)
  File "D:\Users\asus\Desktop\youxi\app\main\utils.py", line 53, in decorate
    return func(dict(username=username, uid=uid, access=access))
  File "D:\Users\asus\Desktop\youxi\app\main\user.py", line 105, in information
    photo=jpg(search.photo))
  File "D:\Users\asus\Desktop\youxi\app\main\utils.py", line 19, in jpg
    return "https://7f1192d863.imdo.co" + x
TypeError: can only concatenate str (not "NoneType") to str
2023-06-16 15:34:42,110 - app - ERROR - Exception on /information [GET]
Traceback (most recent call last):
  File "C:\Users\asus\AppData\Roaming\Python\Python310\site-packages\flask\app.py", line 2525, in wsgi_app
    response = self.full_dispatch_request()
  File "C:\Users\asus\AppData\Roaming\Python\Python310\site-packages\flask\app.py", line 1822, in full_dispatch_request
    rv = self.handle_user_exception(e)
  File "D:\Users\asus\Desktop\youxi\venv\lib\site-packages\flask_cors\extension.py", line 165, in wrapped_function
    return cors_after_request(app.make_response(f(*args, **kwargs)))
  File "C:\Users\asus\AppData\Roaming\Python\Python310\site-packages\flask\app.py", line 1820, in full_dispatch_request
    rv = self.dispatch_request()
  File "C:\Users\asus\AppData\Roaming\Python\Python310\site-packages\flask\app.py", line 1796, in dispatch_request
    return self.ensure_sync(self.view_functions[rule.endpoint])(**view_args)
  File "D:\Users\asus\Desktop\youxi\app\main\utils.py", line 53, in decorate
    return func(dict(username=username, uid=uid, access=access))
  File "D:\Users\asus\Desktop\youxi\app\main\user.py", line 105, in information
    photo=jpg(search.photo))
  File "D:\Users\asus\Desktop\youxi\app\main\utils.py", line 19, in jpg
    return "https://7f1192d863.imdo.co" + x
TypeError: can only concatenate str (not "NoneType") to str
2023-06-16 15:34:46,070 - app - ERROR - Exception on /information [GET]
Traceback (most recent call last):
  File "C:\Users\asus\AppData\Roaming\Python\Python310\site-packages\flask\app.py", line 2525, in wsgi_app
    response = self.full_dispatch_request()
  File "C:\Users\asus\AppData\Roaming\Python\Python310\site-packages\flask\app.py", line 1822, in full_dispatch_request
    rv = self.handle_user_exception(e)
  File "D:\Users\asus\Desktop\youxi\venv\lib\site-packages\flask_cors\extension.py", line 165, in wrapped_function
    return cors_after_request(app.make_response(f(*args, **kwargs)))
  File "C:\Users\asus\AppData\Roaming\Python\Python310\site-packages\flask\app.py", line 1820, in full_dispatch_request
    rv = self.dispatch_request()
  File "C:\Users\asus\AppData\Roaming\Python\Python310\site-packages\flask\app.py", line 1796, in dispatch_request
    return self.ensure_sync(self.view_functions[rule.endpoint])(**view_args)
  File "D:\Users\asus\Desktop\youxi\app\main\utils.py", line 53, in decorate
    return func(dict(username=username, uid=uid, access=access))
  File "D:\Users\asus\Desktop\youxi\app\main\user.py", line 105, in information
    photo=jpg(search.photo))
  File "D:\Users\asus\Desktop\youxi\app\main\utils.py", line 19, in jpg
    return "https://7f1192d863.imdo.co" + x
TypeError: can only concatenate str (not "NoneType") to str
2023-06-16 15:34:57,865 - app - ERROR - Exception on /information [GET]
Traceback (most recent call last):
  File "C:\Users\asus\AppData\Roaming\Python\Python310\site-packages\flask\app.py", line 2525, in wsgi_app
    response = self.full_dispatch_request()
  File "C:\Users\asus\AppData\Roaming\Python\Python310\site-packages\flask\app.py", line 1822, in full_dispatch_request
    rv = self.handle_user_exception(e)
  File "D:\Users\asus\Desktop\youxi\venv\lib\site-packages\flask_cors\extension.py", line 165, in wrapped_function
    return cors_after_request(app.make_response(f(*args, **kwargs)))
  File "C:\Users\asus\AppData\Roaming\Python\Python310\site-packages\flask\app.py", line 1820, in full_dispatch_request
    rv = self.dispatch_request()
  File "C:\Users\asus\AppData\Roaming\Python\Python310\site-packages\flask\app.py", line 1796, in dispatch_request
    return self.ensure_sync(self.view_functions[rule.endpoint])(**view_args)
  File "D:\Users\asus\Desktop\youxi\app\main\utils.py", line 53, in decorate
    return func(dict(username=username, uid=uid, access=access))
  File "D:\Users\asus\Desktop\youxi\app\main\user.py", line 105, in information
    photo=jpg(search.photo))
  File "D:\Users\asus\Desktop\youxi\app\main\utils.py", line 19, in jpg
    return "https://7f1192d863.imdo.co" + x
TypeError: can only concatenate str (not "NoneType") to str
2023-06-16 15:36:06,489 - app - ERROR - Exception on /information [GET]
Traceback (most recent call last):
  File "C:\Users\asus\AppData\Roaming\Python\Python310\site-packages\flask\app.py", line 2525, in wsgi_app
    response = self.full_dispatch_request()
  File "C:\Users\asus\AppData\Roaming\Python\Python310\site-packages\flask\app.py", line 1822, in full_dispatch_request
    rv = self.handle_user_exception(e)
  File "D:\Users\asus\Desktop\youxi\venv\lib\site-packages\flask_cors\extension.py", line 165, in wrapped_function
    return cors_after_request(app.make_response(f(*args, **kwargs)))
  File "C:\Users\asus\AppData\Roaming\Python\Python310\site-packages\flask\app.py", line 1820, in full_dispatch_request
    rv = self.dispatch_request()
  File "C:\Users\asus\AppData\Roaming\Python\Python310\site-packages\flask\app.py", line 1796, in dispatch_request
    return self.ensure_sync(self.view_functions[rule.endpoint])(**view_args)
  File "D:\Users\asus\Desktop\youxi\app\main\utils.py", line 53, in decorate
    return func(dict(username=username, uid=uid, access=access))
  File "D:\Users\asus\Desktop\youxi\app\main\user.py", line 105, in information
    photo=jpg(search.photo))
  File "D:\Users\asus\Desktop\youxi\app\main\utils.py", line 19, in jpg
    return "https://7f1192d863.imdo.co" + x
TypeError: can only concatenate str (not "NoneType") to str
2023-06-16 15:36:41,198 - app - ERROR - Exception on /information [GET]
Traceback (most recent call last):
  File "C:\Users\asus\AppData\Roaming\Python\Python310\site-packages\flask\app.py", line 2525, in wsgi_app
    response = self.full_dispatch_request()
  File "C:\Users\asus\AppData\Roaming\Python\Python310\site-packages\flask\app.py", line 1822, in full_dispatch_request
    rv = self.handle_user_exception(e)
  File "D:\Users\asus\Desktop\youxi\venv\lib\site-packages\flask_cors\extension.py", line 165, in wrapped_function
    return cors_after_request(app.make_response(f(*args, **kwargs)))
  File "C:\Users\asus\AppData\Roaming\Python\Python310\site-packages\flask\app.py", line 1820, in full_dispatch_request
    rv = self.dispatch_request()
  File "C:\Users\asus\AppData\Roaming\Python\Python310\site-packages\flask\app.py", line 1796, in dispatch_request
    return self.ensure_sync(self.view_functions[rule.endpoint])(**view_args)
  File "D:\Users\asus\Desktop\youxi\app\main\utils.py", line 53, in decorate
    return func(dict(username=username, uid=uid, access=access))
  File "D:\Users\asus\Desktop\youxi\app\main\user.py", line 105, in information
    photo=jpg(search.photo))
  File "D:\Users\asus\Desktop\youxi\app\main\utils.py", line 19, in jpg
    return "https://7f1192d863.imdo.co" + x
TypeError: can only concatenate str (not "NoneType") to str
2023-06-16 15:36:50,028 - app - ERROR - Exception on /information [GET]
Traceback (most recent call last):
  File "C:\Users\asus\AppData\Roaming\Python\Python310\site-packages\flask\app.py", line 2525, in wsgi_app
    response = self.full_dispatch_request()
  File "C:\Users\asus\AppData\Roaming\Python\Python310\site-packages\flask\app.py", line 1822, in full_dispatch_request
    rv = self.handle_user_exception(e)
  File "D:\Users\asus\Desktop\youxi\venv\lib\site-packages\flask_cors\extension.py", line 165, in wrapped_function
    return cors_after_request(app.make_response(f(*args, **kwargs)))
  File "C:\Users\asus\AppData\Roaming\Python\Python310\site-packages\flask\app.py", line 1820, in full_dispatch_request
    rv = self.dispatch_request()
  File "C:\Users\asus\AppData\Roaming\Python\Python310\site-packages\flask\app.py", line 1796, in dispatch_request
    return self.ensure_sync(self.view_functions[rule.endpoint])(**view_args)
  File "D:\Users\asus\Desktop\youxi\app\main\utils.py", line 53, in decorate
    return func(dict(username=username, uid=uid, access=access))
  File "D:\Users\asus\Desktop\youxi\app\main\user.py", line 105, in information
    photo=jpg(search.photo))
  File "D:\Users\asus\Desktop\youxi\app\main\utils.py", line 19, in jpg
    return "https://7f1192d863.imdo.co" + x
TypeError: can only concatenate str (not "NoneType") to str
2023-06-16 15:38:09,239 - app - ERROR - Exception on /information [GET]
Traceback (most recent call last):
  File "C:\Users\asus\AppData\Roaming\Python\Python310\site-packages\flask\app.py", line 2525, in wsgi_app
    response = self.full_dispatch_request()
  File "C:\Users\asus\AppData\Roaming\Python\Python310\site-packages\flask\app.py", line 1822, in full_dispatch_request
    rv = self.handle_user_exception(e)
  File "D:\Users\asus\Desktop\youxi\venv\lib\site-packages\flask_cors\extension.py", line 165, in wrapped_function
    return cors_after_request(app.make_response(f(*args, **kwargs)))
  File "C:\Users\asus\AppData\Roaming\Python\Python310\site-packages\flask\app.py", line 1820, in full_dispatch_request
    rv = self.dispatch_request()
  File "C:\Users\asus\AppData\Roaming\Python\Python310\site-packages\flask\app.py", line 1796, in dispatch_request
    return self.ensure_sync(self.view_functions[rule.endpoint])(**view_args)
  File "D:\Users\asus\Desktop\youxi\app\main\utils.py", line 53, in decorate
    return func(dict(username=username, uid=uid, access=access))
  File "D:\Users\asus\Desktop\youxi\app\main\user.py", line 105, in information
    photo=jpg(search.photo))
  File "D:\Users\asus\Desktop\youxi\app\main\utils.py", line 19, in jpg
    return "https://7f1192d863.imdo.co" + x
TypeError: can only concatenate str (not "NoneType") to str
2023-06-16 15:38:16,731 - app - ERROR - Exception on /information [GET]
Traceback (most recent call last):
  File "C:\Users\asus\AppData\Roaming\Python\Python310\site-packages\flask\app.py", line 2525, in wsgi_app
    response = self.full_dispatch_request()
  File "C:\Users\asus\AppData\Roaming\Python\Python310\site-packages\flask\app.py", line 1822, in full_dispatch_request
    rv = self.handle_user_exception(e)
  File "D:\Users\asus\Desktop\youxi\venv\lib\site-packages\flask_cors\extension.py", line 165, in wrapped_function
    return cors_after_request(app.make_response(f(*args, **kwargs)))
  File "C:\Users\asus\AppData\Roaming\Python\Python310\site-packages\flask\app.py", line 1820, in full_dispatch_request
    rv = self.dispatch_request()
  File "C:\Users\asus\AppData\Roaming\Python\Python310\site-packages\flask\app.py", line 1796, in dispatch_request
    return self.ensure_sync(self.view_functions[rule.endpoint])(**view_args)
  File "D:\Users\asus\Desktop\youxi\app\main\utils.py", line 53, in decorate
    return func(dict(username=username, uid=uid, access=access))
  File "D:\Users\asus\Desktop\youxi\app\main\user.py", line 105, in information
    photo=jpg(search.photo))
  File "D:\Users\asus\Desktop\youxi\app\main\utils.py", line 19, in jpg
    return "https://7f1192d863.imdo.co" + x
TypeError: can only concatenate str (not "NoneType") to str
2023-06-16 15:38:20,518 - app - ERROR - Exception on /information [GET]
Traceback (most recent call last):
  File "C:\Users\asus\AppData\Roaming\Python\Python310\site-packages\flask\app.py", line 2525, in wsgi_app
    response = self.full_dispatch_request()
  File "C:\Users\asus\AppData\Roaming\Python\Python310\site-packages\flask\app.py", line 1822, in full_dispatch_request
    rv = self.handle_user_exception(e)
  File "D:\Users\asus\Desktop\youxi\venv\lib\site-packages\flask_cors\extension.py", line 165, in wrapped_function
    return cors_after_request(app.make_response(f(*args, **kwargs)))
  File "C:\Users\asus\AppData\Roaming\Python\Python310\site-packages\flask\app.py", line 1820, in full_dispatch_request
    rv = self.dispatch_request()
  File "C:\Users\asus\AppData\Roaming\Python\Python310\site-packages\flask\app.py", line 1796, in dispatch_request
    return self.ensure_sync(self.view_functions[rule.endpoint])(**view_args)
  File "D:\Users\asus\Desktop\youxi\app\main\utils.py", line 53, in decorate
    return func(dict(username=username, uid=uid, access=access))
  File "D:\Users\asus\Desktop\youxi\app\main\user.py", line 105, in information
    photo=jpg(search.photo))
  File "D:\Users\asus\Desktop\youxi\app\main\utils.py", line 19, in jpg
    return "https://7f1192d863.imdo.co" + x
TypeError: can only concatenate str (not "NoneType") to str
2023-06-16 15:39:29,475 - app - ERROR - Exception on /information [GET]
Traceback (most recent call last):
  File "C:\Users\asus\AppData\Roaming\Python\Python310\site-packages\flask\app.py", line 2525, in wsgi_app
    response = self.full_dispatch_request()
  File "C:\Users\asus\AppData\Roaming\Python\Python310\site-packages\flask\app.py", line 1822, in full_dispatch_request
    rv = self.handle_user_exception(e)
  File "D:\Users\asus\Desktop\youxi\venv\lib\site-packages\flask_cors\extension.py", line 165, in wrapped_function
    return cors_after_request(app.make_response(f(*args, **kwargs)))
  File "C:\Users\asus\AppData\Roaming\Python\Python310\site-packages\flask\app.py", line 1820, in full_dispatch_request
    rv = self.dispatch_request()
  File "C:\Users\asus\AppData\Roaming\Python\Python310\site-packages\flask\app.py", line 1796, in dispatch_request
    return self.ensure_sync(self.view_functions[rule.endpoint])(**view_args)
  File "D:\Users\asus\Desktop\youxi\app\main\utils.py", line 53, in decorate
    return func(dict(username=username, uid=uid, access=access))
  File "D:\Users\asus\Desktop\youxi\app\main\user.py", line 105, in information
    photo=jpg(search.photo))
  File "D:\Users\asus\Desktop\youxi\app\main\utils.py", line 19, in jpg
    return "https://7f1192d863.imdo.co" + x
TypeError: can only concatenate str (not "NoneType") to str
2023-06-16 15:52:31,548 - app - ERROR - Exception on /bid/searching [GET]
Traceback (most recent call last):
  File "C:\Users\asus\AppData\Roaming\Python\Python310\site-packages\flask\app.py", line 2525, in wsgi_app
    response = self.full_dispatch_request()
  File "C:\Users\asus\AppData\Roaming\Python\Python310\site-packages\flask\app.py", line 1822, in full_dispatch_request
    rv = self.handle_user_exception(e)
  File "D:\Users\asus\Desktop\youxi\venv\lib\site-packages\flask_cors\extension.py", line 165, in wrapped_function
    return cors_after_request(app.make_response(f(*args, **kwargs)))
  File "C:\Users\asus\AppData\Roaming\Python\Python310\site-packages\flask\app.py", line 1820, in full_dispatch_request
    rv = self.dispatch_request()
  File "C:\Users\asus\AppData\Roaming\Python\Python310\site-packages\flask\app.py", line 1796, in dispatch_request
    return self.ensure_sync(self.view_functions[rule.endpoint])(**view_args)
TypeError: bid_searching() missing 1 required positional argument: 'x'
2023-06-16 15:52:36,014 - app - ERROR - Exception on /bid/searching [GET]
Traceback (most recent call last):
  File "C:\Users\asus\AppData\Roaming\Python\Python310\site-packages\flask\app.py", line 2525, in wsgi_app
    response = self.full_dispatch_request()
  File "C:\Users\asus\AppData\Roaming\Python\Python310\site-packages\flask\app.py", line 1822, in full_dispatch_request
    rv = self.handle_user_exception(e)
  File "D:\Users\asus\Desktop\youxi\venv\lib\site-packages\flask_cors\extension.py", line 165, in wrapped_function
    return cors_after_request(app.make_response(f(*args, **kwargs)))
  File "C:\Users\asus\AppData\Roaming\Python\Python310\site-packages\flask\app.py", line 1820, in full_dispatch_request
    rv = self.dispatch_request()
  File "C:\Users\asus\AppData\Roaming\Python\Python310\site-packages\flask\app.py", line 1796, in dispatch_request
    return self.ensure_sync(self.view_functions[rule.endpoint])(**view_args)
TypeError: bid_searching() missing 1 required positional argument: 'x'
2023-06-16 15:52:36,907 - app - ERROR - Exception on /bid/searching [GET]
Traceback (most recent call last):
  File "C:\Users\asus\AppData\Roaming\Python\Python310\site-packages\flask\app.py", line 2525, in wsgi_app
    response = self.full_dispatch_request()
  File "C:\Users\asus\AppData\Roaming\Python\Python310\site-packages\flask\app.py", line 1822, in full_dispatch_request
    rv = self.handle_user_exception(e)
  File "D:\Users\asus\Desktop\youxi\venv\lib\site-packages\flask_cors\extension.py", line 165, in wrapped_function
    return cors_after_request(app.make_response(f(*args, **kwargs)))
  File "C:\Users\asus\AppData\Roaming\Python\Python310\site-packages\flask\app.py", line 1820, in full_dispatch_request
    rv = self.dispatch_request()
  File "C:\Users\asus\AppData\Roaming\Python\Python310\site-packages\flask\app.py", line 1796, in dispatch_request
    return self.ensure_sync(self.view_functions[rule.endpoint])(**view_args)
TypeError: bid_searching() missing 1 required positional argument: 'x'
2023-06-16 15:52:38,139 - app - ERROR - Exception on /bid/searching [GET]
Traceback (most recent call last):
  File "C:\Users\asus\AppData\Roaming\Python\Python310\site-packages\flask\app.py", line 2525, in wsgi_app
    response = self.full_dispatch_request()
  File "C:\Users\asus\AppData\Roaming\Python\Python310\site-packages\flask\app.py", line 1822, in full_dispatch_request
    rv = self.handle_user_exception(e)
  File "D:\Users\asus\Desktop\youxi\venv\lib\site-packages\flask_cors\extension.py", line 165, in wrapped_function
    return cors_after_request(app.make_response(f(*args, **kwargs)))
  File "C:\Users\asus\AppData\Roaming\Python\Python310\site-packages\flask\app.py", line 1820, in full_dispatch_request
    rv = self.dispatch_request()
  File "C:\Users\asus\AppData\Roaming\Python\Python310\site-packages\flask\app.py", line 1796, in dispatch_request
    return self.ensure_sync(self.view_functions[rule.endpoint])(**view_args)
TypeError: bid_searching() missing 1 required positional argument: 'x'
2023-06-16 15:52:45,674 - app - ERROR - Exception on /bid/searching [GET]
Traceback (most recent call last):
  File "C:\Users\asus\AppData\Roaming\Python\Python310\site-packages\flask\app.py", line 2525, in wsgi_app
    response = self.full_dispatch_request()
  File "C:\Users\asus\AppData\Roaming\Python\Python310\site-packages\flask\app.py", line 1822, in full_dispatch_request
    rv = self.handle_user_exception(e)
  File "D:\Users\asus\Desktop\youxi\venv\lib\site-packages\flask_cors\extension.py", line 165, in wrapped_function
    return cors_after_request(app.make_response(f(*args, **kwargs)))
  File "C:\Users\asus\AppData\Roaming\Python\Python310\site-packages\flask\app.py", line 1820, in full_dispatch_request
    rv = self.dispatch_request()
  File "C:\Users\asus\AppData\Roaming\Python\Python310\site-packages\flask\app.py", line 1796, in dispatch_request
    return self.ensure_sync(self.view_functions[rule.endpoint])(**view_args)
TypeError: bid_searching() missing 1 required positional argument: 'x'
2023-06-16 15:52:46,809 - app - ERROR - Exception on /bid/searching [GET]
Traceback (most recent call last):
  File "C:\Users\asus\AppData\Roaming\Python\Python310\site-packages\flask\app.py", line 2525, in wsgi_app
    response = self.full_dispatch_request()
  File "C:\Users\asus\AppData\Roaming\Python\Python310\site-packages\flask\app.py", line 1822, in full_dispatch_request
    rv = self.handle_user_exception(e)
  File "D:\Users\asus\Desktop\youxi\venv\lib\site-packages\flask_cors\extension.py", line 165, in wrapped_function
    return cors_after_request(app.make_response(f(*args, **kwargs)))
  File "C:\Users\asus\AppData\Roaming\Python\Python310\site-packages\flask\app.py", line 1820, in full_dispatch_request
    rv = self.dispatch_request()
  File "C:\Users\asus\AppData\Roaming\Python\Python310\site-packages\flask\app.py", line 1796, in dispatch_request
    return self.ensure_sync(self.view_functions[rule.endpoint])(**view_args)
TypeError: bid_searching() missing 1 required positional argument: 'x'
2023-06-16 15:52:49,874 - app - ERROR - Exception on /bid/searching [GET]
Traceback (most recent call last):
  File "C:\Users\asus\AppData\Roaming\Python\Python310\site-packages\flask\app.py", line 2525, in wsgi_app
    response = self.full_dispatch_request()
  File "C:\Users\asus\AppData\Roaming\Python\Python310\site-packages\flask\app.py", line 1822, in full_dispatch_request
    rv = self.handle_user_exception(e)
  File "D:\Users\asus\Desktop\youxi\venv\lib\site-packages\flask_cors\extension.py", line 165, in wrapped_function
    return cors_after_request(app.make_response(f(*args, **kwargs)))
  File "C:\Users\asus\AppData\Roaming\Python\Python310\site-packages\flask\app.py", line 1820, in full_dispatch_request
    rv = self.dispatch_request()
  File "C:\Users\asus\AppData\Roaming\Python\Python310\site-packages\flask\app.py", line 1796, in dispatch_request
    return self.ensure_sync(self.view_functions[rule.endpoint])(**view_args)
TypeError: bid_searching() missing 1 required positional argument: 'x'
2023-06-16 15:53:02,940 - app - ERROR - Exception on /bid/searching [GET]
Traceback (most recent call last):
  File "C:\Users\asus\AppData\Roaming\Python\Python310\site-packages\flask\app.py", line 2525, in wsgi_app
    response = self.full_dispatch_request()
  File "C:\Users\asus\AppData\Roaming\Python\Python310\site-packages\flask\app.py", line 1822, in full_dispatch_request
    rv = self.handle_user_exception(e)
  File "D:\Users\asus\Desktop\youxi\venv\lib\site-packages\flask_cors\extension.py", line 165, in wrapped_function
    return cors_after_request(app.make_response(f(*args, **kwargs)))
  File "C:\Users\asus\AppData\Roaming\Python\Python310\site-packages\flask\app.py", line 1820, in full_dispatch_request
    rv = self.dispatch_request()
  File "C:\Users\asus\AppData\Roaming\Python\Python310\site-packages\flask\app.py", line 1796, in dispatch_request
    return self.ensure_sync(self.view_functions[rule.endpoint])(**view_args)
TypeError: bid_searching() missing 1 required positional argument: 'x'
2023-06-16 15:53:15,551 - app - ERROR - Exception on /bid/searching [GET]
Traceback (most recent call last):
  File "C:\Users\asus\AppData\Roaming\Python\Python310\site-packages\flask\app.py", line 2525, in wsgi_app
    response = self.full_dispatch_request()
  File "C:\Users\asus\AppData\Roaming\Python\Python310\site-packages\flask\app.py", line 1822, in full_dispatch_request
    rv = self.handle_user_exception(e)
  File "D:\Users\asus\Desktop\youxi\venv\lib\site-packages\flask_cors\extension.py", line 165, in wrapped_function
    return cors_after_request(app.make_response(f(*args, **kwargs)))
  File "C:\Users\asus\AppData\Roaming\Python\Python310\site-packages\flask\app.py", line 1820, in full_dispatch_request
    rv = self.dispatch_request()
  File "C:\Users\asus\AppData\Roaming\Python\Python310\site-packages\flask\app.py", line 1796, in dispatch_request
    return self.ensure_sync(self.view_functions[rule.endpoint])(**view_args)
TypeError: bid_searching() missing 1 required positional argument: 'x'
2023-06-16 15:55:07,900 - app - ERROR - Exception on /user/information [GET]
Traceback (most recent call last):
  File "C:\Users\asus\AppData\Roaming\Python\Python310\site-packages\flask\app.py", line 2525, in wsgi_app
    response = self.full_dispatch_request()
  File "C:\Users\asus\AppData\Roaming\Python\Python310\site-packages\flask\app.py", line 1822, in full_dispatch_request
    rv = self.handle_user_exception(e)
  File "D:\Users\asus\Desktop\youxi\venv\lib\site-packages\flask_cors\extension.py", line 165, in wrapped_function
    return cors_after_request(app.make_response(f(*args, **kwargs)))
  File "C:\Users\asus\AppData\Roaming\Python\Python310\site-packages\flask\app.py", line 1820, in full_dispatch_request
    rv = self.dispatch_request()
  File "C:\Users\asus\AppData\Roaming\Python\Python310\site-packages\flask\app.py", line 1796, in dispatch_request
    return self.ensure_sync(self.view_functions[rule.endpoint])(**view_args)
TypeError: user_information() missing 1 required positional argument: 'x'
2023-06-16 15:55:11,425 - app - ERROR - Exception on /user/information [GET]
Traceback (most recent call last):
  File "C:\Users\asus\AppData\Roaming\Python\Python310\site-packages\flask\app.py", line 2525, in wsgi_app
    response = self.full_dispatch_request()
  File "C:\Users\asus\AppData\Roaming\Python\Python310\site-packages\flask\app.py", line 1822, in full_dispatch_request
    rv = self.handle_user_exception(e)
  File "D:\Users\asus\Desktop\youxi\venv\lib\site-packages\flask_cors\extension.py", line 165, in wrapped_function
    return cors_after_request(app.make_response(f(*args, **kwargs)))
  File "C:\Users\asus\AppData\Roaming\Python\Python310\site-packages\flask\app.py", line 1820, in full_dispatch_request
    rv = self.dispatch_request()
  File "C:\Users\asus\AppData\Roaming\Python\Python310\site-packages\flask\app.py", line 1796, in dispatch_request
    return self.ensure_sync(self.view_functions[rule.endpoint])(**view_args)
TypeError: user_information() missing 1 required positional argument: 'x'
2023-06-16 15:55:14,261 - app - ERROR - Exception on /user/information [GET]
Traceback (most recent call last):
  File "C:\Users\asus\AppData\Roaming\Python\Python310\site-packages\flask\app.py", line 2525, in wsgi_app
    response = self.full_dispatch_request()
  File "C:\Users\asus\AppData\Roaming\Python\Python310\site-packages\flask\app.py", line 1822, in full_dispatch_request
    rv = self.handle_user_exception(e)
  File "D:\Users\asus\Desktop\youxi\venv\lib\site-packages\flask_cors\extension.py", line 165, in wrapped_function
    return cors_after_request(app.make_response(f(*args, **kwargs)))
  File "C:\Users\asus\AppData\Roaming\Python\Python310\site-packages\flask\app.py", line 1820, in full_dispatch_request
    rv = self.dispatch_request()
  File "C:\Users\asus\AppData\Roaming\Python\Python310\site-packages\flask\app.py", line 1796, in dispatch_request
    return self.ensure_sync(self.view_functions[rule.endpoint])(**view_args)
TypeError: user_information() missing 1 required positional argument: 'x'
2023-06-16 15:55:19,353 - app - ERROR - Exception on /user/information [GET]
Traceback (most recent call last):
  File "C:\Users\asus\AppData\Roaming\Python\Python310\site-packages\flask\app.py", line 2525, in wsgi_app
    response = self.full_dispatch_request()
  File "C:\Users\asus\AppData\Roaming\Python\Python310\site-packages\flask\app.py", line 1822, in full_dispatch_request
    rv = self.handle_user_exception(e)
  File "D:\Users\asus\Desktop\youxi\venv\lib\site-packages\flask_cors\extension.py", line 165, in wrapped_function
    return cors_after_request(app.make_response(f(*args, **kwargs)))
  File "C:\Users\asus\AppData\Roaming\Python\Python310\site-packages\flask\app.py", line 1820, in full_dispatch_request
    rv = self.dispatch_request()
  File "C:\Users\asus\AppData\Roaming\Python\Python310\site-packages\flask\app.py", line 1796, in dispatch_request
    return self.ensure_sync(self.view_functions[rule.endpoint])(**view_args)
TypeError: user_information() missing 1 required positional argument: 'x'
2023-06-16 15:58:27,100 - app - ERROR - Exception on /exception/100 [POST]
Traceback (most recent call last):
  File "C:\Users\asus\AppData\Local\Programs\Python\Python310\lib\site-packages\sqlalchemy\engine\base.py", line 1900, in _execute_context
    self.dialect.do_execute(
  File "C:\Users\asus\AppData\Local\Programs\Python\Python310\lib\site-packages\sqlalchemy\engine\default.py", line 736, in do_execute
    cursor.execute(statement, parameters)
  File "C:\Users\asus\AppData\Local\Programs\Python\Python310\lib\site-packages\pymysql\cursors.py", line 148, in execute
    result = self._query(query)
  File "C:\Users\asus\AppData\Local\Programs\Python\Python310\lib\site-packages\pymysql\cursors.py", line 310, in _query
    conn.query(q)
  File "C:\Users\asus\AppData\Local\Programs\Python\Python310\lib\site-packages\pymysql\connections.py", line 548, in query
    self._affected_rows = self._read_query_result(unbuffered=unbuffered)
  File "C:\Users\asus\AppData\Local\Programs\Python\Python310\lib\site-packages\pymysql\connections.py", line 775, in _read_query_result
    result.read()
  File "C:\Users\asus\AppData\Local\Programs\Python\Python310\lib\site-packages\pymysql\connections.py", line 1156, in read
    first_packet = self.connection._read_packet()
  File "C:\Users\asus\AppData\Local\Programs\Python\Python310\lib\site-packages\pymysql\connections.py", line 725, in _read_packet
    packet.raise_for_error()
  File "C:\Users\asus\AppData\Local\Programs\Python\Python310\lib\site-packages\pymysql\protocol.py", line 221, in raise_for_error
    err.raise_mysql_exception(self._data)
  File "C:\Users\asus\AppData\Local\Programs\Python\Python310\lib\site-packages\pymysql\err.py", line 143, in raise_mysql_exception
    raise errorclass(errno, errval)
pymysql.err.DataError: (1265, "Data truncated for column 'status' at row 1")

The above exception was the direct cause of the following exception:

Traceback (most recent call last):
  File "D:\Users\asus\Desktop\youxi\app\main\exception.py", line 23, in exception_100
    orders.query.filter(orders.id == order_id).update({"status": "异常1"})
  File "C:\Users\asus\AppData\Local\Programs\Python\Python310\lib\site-packages\sqlalchemy\orm\query.py", line 3306, in update
    result = self.session.execute(
  File "C:\Users\asus\AppData\Local\Programs\Python\Python310\lib\site-packages\sqlalchemy\orm\session.py", line 1714, in execute
    result = conn._execute_20(statement, params or {}, execution_options)
  File "C:\Users\asus\AppData\Local\Programs\Python\Python310\lib\site-packages\sqlalchemy\engine\base.py", line 1705, in _execute_20
    return meth(self, args_10style, kwargs_10style, execution_options)
  File "C:\Users\asus\AppData\Local\Programs\Python\Python310\lib\site-packages\sqlalchemy\sql\elements.py", line 334, in _execute_on_connection
    return connection._execute_clauseelement(
  File "C:\Users\asus\AppData\Local\Programs\Python\Python310\lib\site-packages\sqlalchemy\engine\base.py", line 1572, in _execute_clauseelement
    ret = self._execute_context(
  File "C:\Users\asus\AppData\Local\Programs\Python\Python310\lib\site-packages\sqlalchemy\engine\base.py", line 1943, in _execute_context
    self._handle_dbapi_exception(
  File "C:\Users\asus\AppData\Local\Programs\Python\Python310\lib\site-packages\sqlalchemy\engine\base.py", line 2124, in _handle_dbapi_exception
    util.raise_(
  File "C:\Users\asus\AppData\Local\Programs\Python\Python310\lib\site-packages\sqlalchemy\util\compat.py", line 211, in raise_
    raise exception
  File "C:\Users\asus\AppData\Local\Programs\Python\Python310\lib\site-packages\sqlalchemy\engine\base.py", line 1900, in _execute_context
    self.dialect.do_execute(
  File "C:\Users\asus\AppData\Local\Programs\Python\Python310\lib\site-packages\sqlalchemy\engine\default.py", line 736, in do_execute
    cursor.execute(statement, parameters)
  File "C:\Users\asus\AppData\Local\Programs\Python\Python310\lib\site-packages\pymysql\cursors.py", line 148, in execute
    result = self._query(query)
  File "C:\Users\asus\AppData\Local\Programs\Python\Python310\lib\site-packages\pymysql\cursors.py", line 310, in _query
    conn.query(q)
  File "C:\Users\asus\AppData\Local\Programs\Python\Python310\lib\site-packages\pymysql\connections.py", line 548, in query
    self._affected_rows = self._read_query_result(unbuffered=unbuffered)
  File "C:\Users\asus\AppData\Local\Programs\Python\Python310\lib\site-packages\pymysql\connections.py", line 775, in _read_query_result
    result.read()
  File "C:\Users\asus\AppData\Local\Programs\Python\Python310\lib\site-packages\pymysql\connections.py", line 1156, in read
    first_packet = self.connection._read_packet()
  File "C:\Users\asus\AppData\Local\Programs\Python\Python310\lib\site-packages\pymysql\connections.py", line 725, in _read_packet
    packet.raise_for_error()
  File "C:\Users\asus\AppData\Local\Programs\Python\Python310\lib\site-packages\pymysql\protocol.py", line 221, in raise_for_error
    err.raise_mysql_exception(self._data)
  File "C:\Users\asus\AppData\Local\Programs\Python\Python310\lib\site-packages\pymysql\err.py", line 143, in raise_mysql_exception
    raise errorclass(errno, errval)
sqlalchemy.exc.DataError: (pymysql.err.DataError) (1265, "Data truncated for column 'status' at row 1")
[SQL: UPDATE orders SET status=%(status)s WHERE orders.id = %(id_1)s]
[parameters: {'status': '异常1', 'id_1': 12}]
(Background on this error at: https://sqlalche.me/e/14/9h9h)

During handling of the above exception, another exception occurred:

Traceback (most recent call last):
  File "C:\Users\asus\AppData\Roaming\Python\Python310\site-packages\flask\app.py", line 2525, in wsgi_app
    response = self.full_dispatch_request()
  File "C:\Users\asus\AppData\Roaming\Python\Python310\site-packages\flask\app.py", line 1822, in full_dispatch_request
    rv = self.handle_user_exception(e)
  File "D:\Users\asus\Desktop\youxi\venv\lib\site-packages\flask_cors\extension.py", line 165, in wrapped_function
    return cors_after_request(app.make_response(f(*args, **kwargs)))
  File "C:\Users\asus\AppData\Roaming\Python\Python310\site-packages\flask\app.py", line 1820, in full_dispatch_request
    rv = self.dispatch_request()
  File "C:\Users\asus\AppData\Roaming\Python\Python310\site-packages\flask\app.py", line 1796, in dispatch_request
    return self.ensure_sync(self.view_functions[rule.endpoint])(**view_args)
  File "D:\Users\asus\Desktop\youxi\app\main\exception.py", line 24, in exception_100
    except exception:
TypeError: catching classes that do not inherit from BaseException is not allowed
2023-06-18 20:35:17,204 - app - ERROR - Exception on /order/deleting [DELETE]
Traceback (most recent call last):
  File "C:\Users\asus\AppData\Roaming\Python\Python310\site-packages\flask\app.py", line 2525, in wsgi_app
    response = self.full_dispatch_request()
  File "C:\Users\asus\AppData\Roaming\Python\Python310\site-packages\flask\app.py", line 1822, in full_dispatch_request
    rv = self.handle_user_exception(e)
  File "D:\Users\asus\Desktop\youxi\venv\lib\site-packages\flask_cors\extension.py", line 165, in wrapped_function
    return cors_after_request(app.make_response(f(*args, **kwargs)))
  File "C:\Users\asus\AppData\Roaming\Python\Python310\site-packages\flask\app.py", line 1820, in full_dispatch_request
    rv = self.dispatch_request()
  File "C:\Users\asus\AppData\Roaming\Python\Python310\site-packages\flask\app.py", line 1796, in dispatch_request
    return self.ensure_sync(self.view_functions[rule.endpoint])(**view_args)
  File "D:\Users\asus\Desktop\youxi\app\main\utils.py", line 53, in decorate
    return func(dict(username=username, uid=uid, access=access))
  File "D:\Users\asus\Desktop\youxi\app\main\view.py", line 461, in order_deleting
    order_id = int(request.args.get("order_id"))
TypeError: int() argument must be a string, a bytes-like object or a real number, not 'NoneType'
2023-06-18 21:58:38,214 - app - ERROR - Exception on /user/information [GET]
Traceback (most recent call last):
  File "C:\Users\asus\AppData\Roaming\Python\Python310\site-packages\flask\app.py", line 2525, in wsgi_app
    response = self.full_dispatch_request()
  File "C:\Users\asus\AppData\Roaming\Python\Python310\site-packages\flask\app.py", line 1822, in full_dispatch_request
    rv = self.handle_user_exception(e)
  File "D:\Users\asus\Desktop\youxi\venv\lib\site-packages\flask_cors\extension.py", line 165, in wrapped_function
    return cors_after_request(app.make_response(f(*args, **kwargs)))
  File "C:\Users\asus\AppData\Roaming\Python\Python310\site-packages\flask\app.py", line 1820, in full_dispatch_request
    rv = self.dispatch_request()
  File "C:\Users\asus\AppData\Roaming\Python\Python310\site-packages\flask\app.py", line 1796, in dispatch_request
    return self.ensure_sync(self.view_functions[rule.endpoint])(**view_args)
  File "D:\Users\asus\Desktop\youxi\app\main\user.py", line 175, in user_information
    name = users.query.filter(users.id == user_id).first().username
AttributeError: 'NoneType' object has no attribute 'username'
2023-06-18 21:59:35,383 - app - ERROR - Exception on /user/information [GET]
Traceback (most recent call last):
  File "C:\Users\asus\AppData\Roaming\Python\Python310\site-packages\flask\app.py", line 2525, in wsgi_app
    response = self.full_dispatch_request()
  File "C:\Users\asus\AppData\Roaming\Python\Python310\site-packages\flask\app.py", line 1822, in full_dispatch_request
    rv = self.handle_user_exception(e)
  File "D:\Users\asus\Desktop\youxi\venv\lib\site-packages\flask_cors\extension.py", line 165, in wrapped_function
    return cors_after_request(app.make_response(f(*args, **kwargs)))
  File "C:\Users\asus\AppData\Roaming\Python\Python310\site-packages\flask\app.py", line 1820, in full_dispatch_request
    rv = self.dispatch_request()
  File "C:\Users\asus\AppData\Roaming\Python\Python310\site-packages\flask\app.py", line 1796, in dispatch_request
    return self.ensure_sync(self.view_functions[rule.endpoint])(**view_args)
  File "D:\Users\asus\Desktop\youxi\app\main\user.py", line 175, in user_information
    name = users.query.filter(users.id == user_id).first().username
AttributeError: 'NoneType' object has no attribute 'username'
2023-06-18 22:00:25,709 - app - ERROR - Exception on /user/information [GET]
Traceback (most recent call last):
  File "C:\Users\asus\AppData\Roaming\Python\Python310\site-packages\flask\app.py", line 2525, in wsgi_app
    response = self.full_dispatch_request()
  File "C:\Users\asus\AppData\Roaming\Python\Python310\site-packages\flask\app.py", line 1822, in full_dispatch_request
    rv = self.handle_user_exception(e)
  File "D:\Users\asus\Desktop\youxi\venv\lib\site-packages\flask_cors\extension.py", line 165, in wrapped_function
    return cors_after_request(app.make_response(f(*args, **kwargs)))
  File "C:\Users\asus\AppData\Roaming\Python\Python310\site-packages\flask\app.py", line 1820, in full_dispatch_request
    rv = self.dispatch_request()
  File "C:\Users\asus\AppData\Roaming\Python\Python310\site-packages\flask\app.py", line 1796, in dispatch_request
    return self.ensure_sync(self.view_functions[rule.endpoint])(**view_args)
  File "D:\Users\asus\Desktop\youxi\app\main\user.py", line 175, in user_information
    name = users.query.filter(users.id == user_id).first().username
AttributeError: 'NoneType' object has no attribute 'username'
2023-06-18 22:00:38,263 - app - ERROR - Exception on /user/information [GET]
Traceback (most recent call last):
  File "C:\Users\asus\AppData\Roaming\Python\Python310\site-packages\flask\app.py", line 2525, in wsgi_app
    response = self.full_dispatch_request()
  File "C:\Users\asus\AppData\Roaming\Python\Python310\site-packages\flask\app.py", line 1822, in full_dispatch_request
    rv = self.handle_user_exception(e)
  File "D:\Users\asus\Desktop\youxi\venv\lib\site-packages\flask_cors\extension.py", line 165, in wrapped_function
    return cors_after_request(app.make_response(f(*args, **kwargs)))
  File "C:\Users\asus\AppData\Roaming\Python\Python310\site-packages\flask\app.py", line 1820, in full_dispatch_request
    rv = self.dispatch_request()
  File "C:\Users\asus\AppData\Roaming\Python\Python310\site-packages\flask\app.py", line 1796, in dispatch_request
    return self.ensure_sync(self.view_functions[rule.endpoint])(**view_args)
  File "D:\Users\asus\Desktop\youxi\app\main\user.py", line 175, in user_information
    name = users.query.filter(users.id == user_id).first().username
AttributeError: 'NoneType' object has no attribute 'username'
2023-06-18 22:01:39,532 - app - ERROR - Exception on /user/information [GET]
Traceback (most recent call last):
  File "C:\Users\asus\AppData\Roaming\Python\Python310\site-packages\flask\app.py", line 2525, in wsgi_app
    response = self.full_dispatch_request()
  File "C:\Users\asus\AppData\Roaming\Python\Python310\site-packages\flask\app.py", line 1822, in full_dispatch_request
    rv = self.handle_user_exception(e)
  File "D:\Users\asus\Desktop\youxi\venv\lib\site-packages\flask_cors\extension.py", line 165, in wrapped_function
    return cors_after_request(app.make_response(f(*args, **kwargs)))
  File "C:\Users\asus\AppData\Roaming\Python\Python310\site-packages\flask\app.py", line 1820, in full_dispatch_request
    rv = self.dispatch_request()
  File "C:\Users\asus\AppData\Roaming\Python\Python310\site-packages\flask\app.py", line 1796, in dispatch_request
    return self.ensure_sync(self.view_functions[rule.endpoint])(**view_args)
  File "D:\Users\asus\Desktop\youxi\app\main\user.py", line 175, in user_information
    name = users.query.filter(users.id == user_id).first().username
AttributeError: 'NoneType' object has no attribute 'username'
2023-06-18 22:01:42,566 - app - ERROR - Exception on /user/information [GET]
Traceback (most recent call last):
  File "C:\Users\asus\AppData\Roaming\Python\Python310\site-packages\flask\app.py", line 2525, in wsgi_app
    response = self.full_dispatch_request()
  File "C:\Users\asus\AppData\Roaming\Python\Python310\site-packages\flask\app.py", line 1822, in full_dispatch_request
    rv = self.handle_user_exception(e)
  File "D:\Users\asus\Desktop\youxi\venv\lib\site-packages\flask_cors\extension.py", line 165, in wrapped_function
    return cors_after_request(app.make_response(f(*args, **kwargs)))
  File "C:\Users\asus\AppData\Roaming\Python\Python310\site-packages\flask\app.py", line 1820, in full_dispatch_request
    rv = self.dispatch_request()
  File "C:\Users\asus\AppData\Roaming\Python\Python310\site-packages\flask\app.py", line 1796, in dispatch_request
    return self.ensure_sync(self.view_functions[rule.endpoint])(**view_args)
  File "D:\Users\asus\Desktop\youxi\app\main\user.py", line 175, in user_information
    name = users.query.filter(users.id == user_id).first().username
AttributeError: 'NoneType' object has no attribute 'username'
2023-06-18 22:24:21,365 - app - ERROR - Exception on /user/information [GET]
Traceback (most recent call last):
  File "C:\Users\asus\AppData\Roaming\Python\Python310\site-packages\flask\app.py", line 2525, in wsgi_app
    response = self.full_dispatch_request()
  File "C:\Users\asus\AppData\Roaming\Python\Python310\site-packages\flask\app.py", line 1822, in full_dispatch_request
    rv = self.handle_user_exception(e)
  File "D:\Users\asus\Desktop\youxi\venv\lib\site-packages\flask_cors\extension.py", line 165, in wrapped_function
    return cors_after_request(app.make_response(f(*args, **kwargs)))
  File "C:\Users\asus\AppData\Roaming\Python\Python310\site-packages\flask\app.py", line 1820, in full_dispatch_request
    rv = self.dispatch_request()
  File "C:\Users\asus\AppData\Roaming\Python\Python310\site-packages\flask\app.py", line 1796, in dispatch_request
    return self.ensure_sync(self.view_functions[rule.endpoint])(**view_args)
  File "D:\Users\asus\Desktop\youxi\app\main\user.py", line 175, in user_information
    name = users.query.filter(users.id == user_id).first().username
AttributeError: 'NoneType' object has no attribute 'username'
2023-06-18 22:24:44,782 - app - ERROR - Exception on /user/information [GET]
Traceback (most recent call last):
  File "C:\Users\asus\AppData\Roaming\Python\Python310\site-packages\flask\app.py", line 2525, in wsgi_app
    response = self.full_dispatch_request()
  File "C:\Users\asus\AppData\Roaming\Python\Python310\site-packages\flask\app.py", line 1822, in full_dispatch_request
    rv = self.handle_user_exception(e)
  File "D:\Users\asus\Desktop\youxi\venv\lib\site-packages\flask_cors\extension.py", line 165, in wrapped_function
    return cors_after_request(app.make_response(f(*args, **kwargs)))
  File "C:\Users\asus\AppData\Roaming\Python\Python310\site-packages\flask\app.py", line 1820, in full_dispatch_request
    rv = self.dispatch_request()
  File "C:\Users\asus\AppData\Roaming\Python\Python310\site-packages\flask\app.py", line 1796, in dispatch_request
    return self.ensure_sync(self.view_functions[rule.endpoint])(**view_args)
  File "D:\Users\asus\Desktop\youxi\app\main\user.py", line 175, in user_information
    name = users.query.filter(users.id == user_id).first().username
AttributeError: 'NoneType' object has no attribute 'username'
2023-06-18 22:30:08,037 - app - ERROR - Exception on /user/information [GET]
Traceback (most recent call last):
  File "C:\Users\asus\AppData\Roaming\Python\Python310\site-packages\flask\app.py", line 2525, in wsgi_app
    response = self.full_dispatch_request()
  File "C:\Users\asus\AppData\Roaming\Python\Python310\site-packages\flask\app.py", line 1822, in full_dispatch_request
    rv = self.handle_user_exception(e)
  File "D:\Users\asus\Desktop\youxi\venv\lib\site-packages\flask_cors\extension.py", line 165, in wrapped_function
    return cors_after_request(app.make_response(f(*args, **kwargs)))
  File "C:\Users\asus\AppData\Roaming\Python\Python310\site-packages\flask\app.py", line 1820, in full_dispatch_request
    rv = self.dispatch_request()
  File "C:\Users\asus\AppData\Roaming\Python\Python310\site-packages\flask\app.py", line 1796, in dispatch_request
    return self.ensure_sync(self.view_functions[rule.endpoint])(**view_args)
  File "D:\Users\asus\Desktop\youxi\app\main\user.py", line 175, in user_information
    name = users.query.filter(users.id == user_id).first().username
AttributeError: 'NoneType' object has no attribute 'username'
2023-06-18 22:30:15,524 - app - ERROR - Exception on /user/information [GET]
Traceback (most recent call last):
  File "C:\Users\asus\AppData\Roaming\Python\Python310\site-packages\flask\app.py", line 2525, in wsgi_app
    response = self.full_dispatch_request()
  File "C:\Users\asus\AppData\Roaming\Python\Python310\site-packages\flask\app.py", line 1822, in full_dispatch_request
    rv = self.handle_user_exception(e)
  File "D:\Users\asus\Desktop\youxi\venv\lib\site-packages\flask_cors\extension.py", line 165, in wrapped_function
    return cors_after_request(app.make_response(f(*args, **kwargs)))
  File "C:\Users\asus\AppData\Roaming\Python\Python310\site-packages\flask\app.py", line 1820, in full_dispatch_request
    rv = self.dispatch_request()
  File "C:\Users\asus\AppData\Roaming\Python\Python310\site-packages\flask\app.py", line 1796, in dispatch_request
    return self.ensure_sync(self.view_functions[rule.endpoint])(**view_args)
  File "D:\Users\asus\Desktop\youxi\app\main\user.py", line 175, in user_information
    name = users.query.filter(users.id == user_id).first().username
AttributeError: 'NoneType' object has no attribute 'username'
2023-06-18 22:30:18,741 - app - ERROR - Exception on /user/information [GET]
Traceback (most recent call last):
  File "C:\Users\asus\AppData\Roaming\Python\Python310\site-packages\flask\app.py", line 2525, in wsgi_app
    response = self.full_dispatch_request()
  File "C:\Users\asus\AppData\Roaming\Python\Python310\site-packages\flask\app.py", line 1822, in full_dispatch_request
    rv = self.handle_user_exception(e)
  File "D:\Users\asus\Desktop\youxi\venv\lib\site-packages\flask_cors\extension.py", line 165, in wrapped_function
    return cors_after_request(app.make_response(f(*args, **kwargs)))
  File "C:\Users\asus\AppData\Roaming\Python\Python310\site-packages\flask\app.py", line 1820, in full_dispatch_request
    rv = self.dispatch_request()
  File "C:\Users\asus\AppData\Roaming\Python\Python310\site-packages\flask\app.py", line 1796, in dispatch_request
    return self.ensure_sync(self.view_functions[rule.endpoint])(**view_args)
  File "D:\Users\asus\Desktop\youxi\app\main\user.py", line 175, in user_information
    name = users.query.filter(users.id == user_id).first().username
AttributeError: 'NoneType' object has no attribute 'username'
2023-06-18 22:30:21,535 - app - ERROR - Exception on /user/information [GET]
Traceback (most recent call last):
  File "C:\Users\asus\AppData\Roaming\Python\Python310\site-packages\flask\app.py", line 2525, in wsgi_app
    response = self.full_dispatch_request()
  File "C:\Users\asus\AppData\Roaming\Python\Python310\site-packages\flask\app.py", line 1822, in full_dispatch_request
    rv = self.handle_user_exception(e)
  File "D:\Users\asus\Desktop\youxi\venv\lib\site-packages\flask_cors\extension.py", line 165, in wrapped_function
    return cors_after_request(app.make_response(f(*args, **kwargs)))
  File "C:\Users\asus\AppData\Roaming\Python\Python310\site-packages\flask\app.py", line 1820, in full_dispatch_request
    rv = self.dispatch_request()
  File "C:\Users\asus\AppData\Roaming\Python\Python310\site-packages\flask\app.py", line 1796, in dispatch_request
    return self.ensure_sync(self.view_functions[rule.endpoint])(**view_args)
  File "D:\Users\asus\Desktop\youxi\app\main\user.py", line 175, in user_information
    name = users.query.filter(users.id == user_id).first().username
AttributeError: 'NoneType' object has no attribute 'username'
2023-06-18 22:30:26,601 - app - ERROR - Exception on /user/information [GET]
Traceback (most recent call last):
  File "C:\Users\asus\AppData\Roaming\Python\Python310\site-packages\flask\app.py", line 2525, in wsgi_app
    response = self.full_dispatch_request()
  File "C:\Users\asus\AppData\Roaming\Python\Python310\site-packages\flask\app.py", line 1822, in full_dispatch_request
    rv = self.handle_user_exception(e)
  File "D:\Users\asus\Desktop\youxi\venv\lib\site-packages\flask_cors\extension.py", line 165, in wrapped_function
    return cors_after_request(app.make_response(f(*args, **kwargs)))
  File "C:\Users\asus\AppData\Roaming\Python\Python310\site-packages\flask\app.py", line 1820, in full_dispatch_request
    rv = self.dispatch_request()
  File "C:\Users\asus\AppData\Roaming\Python\Python310\site-packages\flask\app.py", line 1796, in dispatch_request
    return self.ensure_sync(self.view_functions[rule.endpoint])(**view_args)
  File "D:\Users\asus\Desktop\youxi\app\main\user.py", line 175, in user_information
    name = users.query.filter(users.id == user_id).first().username
AttributeError: 'NoneType' object has no attribute 'username'
2023-06-18 22:30:28,364 - app - ERROR - Exception on /user/information [GET]
Traceback (most recent call last):
  File "C:\Users\asus\AppData\Roaming\Python\Python310\site-packages\flask\app.py", line 2525, in wsgi_app
    response = self.full_dispatch_request()
  File "C:\Users\asus\AppData\Roaming\Python\Python310\site-packages\flask\app.py", line 1822, in full_dispatch_request
    rv = self.handle_user_exception(e)
  File "D:\Users\asus\Desktop\youxi\venv\lib\site-packages\flask_cors\extension.py", line 165, in wrapped_function
    return cors_after_request(app.make_response(f(*args, **kwargs)))
  File "C:\Users\asus\AppData\Roaming\Python\Python310\site-packages\flask\app.py", line 1820, in full_dispatch_request
    rv = self.dispatch_request()
  File "C:\Users\asus\AppData\Roaming\Python\Python310\site-packages\flask\app.py", line 1796, in dispatch_request
    return self.ensure_sync(self.view_functions[rule.endpoint])(**view_args)
  File "D:\Users\asus\Desktop\youxi\app\main\user.py", line 175, in user_information
    name = users.query.filter(users.id == user_id).first().username
AttributeError: 'NoneType' object has no attribute 'username'
2023-06-18 22:30:29,777 - app - ERROR - Exception on /user/information [GET]
Traceback (most recent call last):
  File "C:\Users\asus\AppData\Roaming\Python\Python310\site-packages\flask\app.py", line 2525, in wsgi_app
    response = self.full_dispatch_request()
  File "C:\Users\asus\AppData\Roaming\Python\Python310\site-packages\flask\app.py", line 1822, in full_dispatch_request
    rv = self.handle_user_exception(e)
  File "D:\Users\asus\Desktop\youxi\venv\lib\site-packages\flask_cors\extension.py", line 165, in wrapped_function
    return cors_after_request(app.make_response(f(*args, **kwargs)))
  File "C:\Users\asus\AppData\Roaming\Python\Python310\site-packages\flask\app.py", line 1820, in full_dispatch_request
    rv = self.dispatch_request()
  File "C:\Users\asus\AppData\Roaming\Python\Python310\site-packages\flask\app.py", line 1796, in dispatch_request
    return self.ensure_sync(self.view_functions[rule.endpoint])(**view_args)
  File "D:\Users\asus\Desktop\youxi\app\main\user.py", line 175, in user_information
    name = users.query.filter(users.id == user_id).first().username
AttributeError: 'NoneType' object has no attribute 'username'
2023-07-03 09:57:18,495 - app - ERROR - Exception on /user/information [GET]
Traceback (most recent call last):
  File "C:\Users\asus\AppData\Roaming\Python\Python310\site-packages\flask\app.py", line 2525, in wsgi_app
    response = self.full_dispatch_request()
  File "C:\Users\asus\AppData\Roaming\Python\Python310\site-packages\flask\app.py", line 1822, in full_dispatch_request
    rv = self.handle_user_exception(e)
  File "D:\Users\asus\Desktop\youxi\venv\lib\site-packages\flask_cors\extension.py", line 165, in wrapped_function
    return cors_after_request(app.make_response(f(*args, **kwargs)))
  File "C:\Users\asus\AppData\Roaming\Python\Python310\site-packages\flask\app.py", line 1820, in full_dispatch_request
    rv = self.dispatch_request()
  File "C:\Users\asus\AppData\Roaming\Python\Python310\site-packages\flask\app.py", line 1796, in dispatch_request
    return self.ensure_sync(self.view_functions[rule.endpoint])(**view_args)
  File "D:\Users\asus\Desktop\youxi\app\main\user.py", line 175, in user_information
    name = users.query.filter(users.id == user_id).first().username
AttributeError: 'NoneType' object has no attribute 'username'
2023-07-03 12:49:54,341 - app - ERROR - Exception on /user/information [GET]
Traceback (most recent call last):
  File "C:\Users\asus\AppData\Roaming\Python\Python310\site-packages\flask\app.py", line 2525, in wsgi_app
    response = self.full_dispatch_request()
  File "C:\Users\asus\AppData\Roaming\Python\Python310\site-packages\flask\app.py", line 1822, in full_dispatch_request
    rv = self.handle_user_exception(e)
  File "D:\Users\asus\Desktop\youxi\venv\lib\site-packages\flask_cors\extension.py", line 165, in wrapped_function
    return cors_after_request(app.make_response(f(*args, **kwargs)))
  File "C:\Users\asus\AppData\Roaming\Python\Python310\site-packages\flask\app.py", line 1820, in full_dispatch_request
    rv = self.dispatch_request()
  File "C:\Users\asus\AppData\Roaming\Python\Python310\site-packages\flask\app.py", line 1796, in dispatch_request
    return self.ensure_sync(self.view_functions[rule.endpoint])(**view_args)
  File "D:\Users\asus\Desktop\youxi\app\main\user.py", line 175, in user_information
    name = users.query.filter(users.id == user_id).first().username
AttributeError: 'NoneType' object has no attribute 'username'
2023-07-03 12:50:04,601 - app - ERROR - Exception on /user/information [GET]
Traceback (most recent call last):
  File "C:\Users\asus\AppData\Roaming\Python\Python310\site-packages\flask\app.py", line 2525, in wsgi_app
    response = self.full_dispatch_request()
  File "C:\Users\asus\AppData\Roaming\Python\Python310\site-packages\flask\app.py", line 1822, in full_dispatch_request
    rv = self.handle_user_exception(e)
  File "D:\Users\asus\Desktop\youxi\venv\lib\site-packages\flask_cors\extension.py", line 165, in wrapped_function
    return cors_after_request(app.make_response(f(*args, **kwargs)))
  File "C:\Users\asus\AppData\Roaming\Python\Python310\site-packages\flask\app.py", line 1820, in full_dispatch_request
    rv = self.dispatch_request()
  File "C:\Users\asus\AppData\Roaming\Python\Python310\site-packages\flask\app.py", line 1796, in dispatch_request
    return self.ensure_sync(self.view_functions[rule.endpoint])(**view_args)
  File "D:\Users\asus\Desktop\youxi\app\main\user.py", line 175, in user_information
    name = users.query.filter(users.id == user_id).first().username
AttributeError: 'NoneType' object has no attribute 'username'
2023-07-03 12:50:05,259 - app - ERROR - Exception on /user/information [GET]
Traceback (most recent call last):
  File "C:\Users\asus\AppData\Roaming\Python\Python310\site-packages\flask\app.py", line 2525, in wsgi_app
    response = self.full_dispatch_request()
  File "C:\Users\asus\AppData\Roaming\Python\Python310\site-packages\flask\app.py", line 1822, in full_dispatch_request
    rv = self.handle_user_exception(e)
  File "D:\Users\asus\Desktop\youxi\venv\lib\site-packages\flask_cors\extension.py", line 165, in wrapped_function
    return cors_after_request(app.make_response(f(*args, **kwargs)))
  File "C:\Users\asus\AppData\Roaming\Python\Python310\site-packages\flask\app.py", line 1820, in full_dispatch_request
    rv = self.dispatch_request()
  File "C:\Users\asus\AppData\Roaming\Python\Python310\site-packages\flask\app.py", line 1796, in dispatch_request
    return self.ensure_sync(self.view_functions[rule.endpoint])(**view_args)
  File "D:\Users\asus\Desktop\youxi\app\main\user.py", line 175, in user_information
    name = users.query.filter(users.id == user_id).first().username
AttributeError: 'NoneType' object has no attribute 'username'
2023-07-03 12:50:06,391 - app - ERROR - Exception on /user/information [GET]
Traceback (most recent call last):
  File "C:\Users\asus\AppData\Roaming\Python\Python310\site-packages\flask\app.py", line 2525, in wsgi_app
    response = self.full_dispatch_request()
  File "C:\Users\asus\AppData\Roaming\Python\Python310\site-packages\flask\app.py", line 1822, in full_dispatch_request
    rv = self.handle_user_exception(e)
  File "D:\Users\asus\Desktop\youxi\venv\lib\site-packages\flask_cors\extension.py", line 165, in wrapped_function
    return cors_after_request(app.make_response(f(*args, **kwargs)))
  File "C:\Users\asus\AppData\Roaming\Python\Python310\site-packages\flask\app.py", line 1820, in full_dispatch_request
    rv = self.dispatch_request()
  File "C:\Users\asus\AppData\Roaming\Python\Python310\site-packages\flask\app.py", line 1796, in dispatch_request
    return self.ensure_sync(self.view_functions[rule.endpoint])(**view_args)
  File "D:\Users\asus\Desktop\youxi\app\main\user.py", line 175, in user_information
    name = users.query.filter(users.id == user_id).first().username
AttributeError: 'NoneType' object has no attribute 'username'
2023-07-03 13:00:34,151 - app - ERROR - Exception on /user/information [GET]
Traceback (most recent call last):
  File "C:\Users\asus\AppData\Roaming\Python\Python310\site-packages\flask\app.py", line 2525, in wsgi_app
    response = self.full_dispatch_request()
  File "C:\Users\asus\AppData\Roaming\Python\Python310\site-packages\flask\app.py", line 1822, in full_dispatch_request
    rv = self.handle_user_exception(e)
  File "D:\Users\asus\Desktop\youxi\venv\lib\site-packages\flask_cors\extension.py", line 165, in wrapped_function
    return cors_after_request(app.make_response(f(*args, **kwargs)))
  File "C:\Users\asus\AppData\Roaming\Python\Python310\site-packages\flask\app.py", line 1820, in full_dispatch_request
    rv = self.dispatch_request()
  File "C:\Users\asus\AppData\Roaming\Python\Python310\site-packages\flask\app.py", line 1796, in dispatch_request
    return self.ensure_sync(self.view_functions[rule.endpoint])(**view_args)
  File "D:\Users\asus\Desktop\youxi\app\main\user.py", line 175, in user_information
    name = users.query.filter(users.id == user_id).first().username
AttributeError: 'NoneType' object has no attribute 'username'
2023-07-03 13:19:24,374 - app - ERROR - Exception on /user/information [GET]
Traceback (most recent call last):
  File "C:\Users\asus\AppData\Roaming\Python\Python310\site-packages\flask\app.py", line 2525, in wsgi_app
    response = self.full_dispatch_request()
  File "C:\Users\asus\AppData\Roaming\Python\Python310\site-packages\flask\app.py", line 1822, in full_dispatch_request
    rv = self.handle_user_exception(e)
  File "D:\Users\asus\Desktop\youxi\venv\lib\site-packages\flask_cors\extension.py", line 165, in wrapped_function
    return cors_after_request(app.make_response(f(*args, **kwargs)))
  File "C:\Users\asus\AppData\Roaming\Python\Python310\site-packages\flask\app.py", line 1820, in full_dispatch_request
    rv = self.dispatch_request()
  File "C:\Users\asus\AppData\Roaming\Python\Python310\site-packages\flask\app.py", line 1796, in dispatch_request
    return self.ensure_sync(self.view_functions[rule.endpoint])(**view_args)
  File "D:\Users\asus\Desktop\youxi\app\main\user.py", line 175, in user_information
    name = users.query.filter(users.id == user_id).first().username
AttributeError: 'NoneType' object has no attribute 'username'
2023-07-03 13:19:26,169 - app - ERROR - Exception on /user/information [GET]
Traceback (most recent call last):
  File "C:\Users\asus\AppData\Roaming\Python\Python310\site-packages\flask\app.py", line 2525, in wsgi_app
    response = self.full_dispatch_request()
  File "C:\Users\asus\AppData\Roaming\Python\Python310\site-packages\flask\app.py", line 1822, in full_dispatch_request
    rv = self.handle_user_exception(e)
  File "D:\Users\asus\Desktop\youxi\venv\lib\site-packages\flask_cors\extension.py", line 165, in wrapped_function
    return cors_after_request(app.make_response(f(*args, **kwargs)))
  File "C:\Users\asus\AppData\Roaming\Python\Python310\site-packages\flask\app.py", line 1820, in full_dispatch_request
    rv = self.dispatch_request()
  File "C:\Users\asus\AppData\Roaming\Python\Python310\site-packages\flask\app.py", line 1796, in dispatch_request
    return self.ensure_sync(self.view_functions[rule.endpoint])(**view_args)
  File "D:\Users\asus\Desktop\youxi\app\main\user.py", line 175, in user_information
    name = users.query.filter(users.id == user_id).first().username
AttributeError: 'NoneType' object has no attribute 'username'
2023-07-06 11:24:18,774 - app - ERROR - Exception on /exception/110 [POST]
Traceback (most recent call last):
  File "C:\Users\asus\AppData\Roaming\Python\Python310\site-packages\flask\app.py", line 2525, in wsgi_app
    response = self.full_dispatch_request()
  File "C:\Users\asus\AppData\Roaming\Python\Python310\site-packages\flask\app.py", line 1822, in full_dispatch_request
    rv = self.handle_user_exception(e)
  File "D:\Users\asus\Desktop\youxi\venv\lib\site-packages\flask_cors\extension.py", line 165, in wrapped_function
    return cors_after_request(app.make_response(f(*args, **kwargs)))
  File "C:\Users\asus\AppData\Roaming\Python\Python310\site-packages\flask\app.py", line 1820, in full_dispatch_request
    rv = self.dispatch_request()
  File "C:\Users\asus\AppData\Roaming\Python\Python310\site-packages\flask\app.py", line 1796, in dispatch_request
    return self.ensure_sync(self.view_functions[rule.endpoint])(**view_args)
  File "D:\Users\asus\Desktop\youxi\app\main\exception.py", line 43, in exception_110
    seller_id = orders.query.filter(orders.id == orders_id).first().seller_id
AttributeError: 'NoneType' object has no attribute 'seller_id'
2023-07-06 11:27:44,280 - app - ERROR - Exception on /exception/110 [POST]
Traceback (most recent call last):
  File "C:\Users\asus\AppData\Roaming\Python\Python310\site-packages\flask\app.py", line 2525, in wsgi_app
    response = self.full_dispatch_request()
  File "C:\Users\asus\AppData\Roaming\Python\Python310\site-packages\flask\app.py", line 1822, in full_dispatch_request
    rv = self.handle_user_exception(e)
  File "D:\Users\asus\Desktop\youxi\venv\lib\site-packages\flask_cors\extension.py", line 165, in wrapped_function
    return cors_after_request(app.make_response(f(*args, **kwargs)))
  File "C:\Users\asus\AppData\Roaming\Python\Python310\site-packages\flask\app.py", line 1820, in full_dispatch_request
    rv = self.dispatch_request()
  File "C:\Users\asus\AppData\Roaming\Python\Python310\site-packages\flask\app.py", line 1796, in dispatch_request
    return self.ensure_sync(self.view_functions[rule.endpoint])(**view_args)
  File "D:\Users\asus\Desktop\youxi\app\main\exception.py", line 43, in exception_110
    seller_id = orders.query.filter(orders.id == orders_id).first().seller_id
AttributeError: 'NoneType' object has no attribute 'seller_id'
2023-07-06 11:27:57,972 - app - ERROR - Exception on /exception/110 [POST]
Traceback (most recent call last):
  File "C:\Users\asus\AppData\Roaming\Python\Python310\site-packages\flask\app.py", line 2525, in wsgi_app
    response = self.full_dispatch_request()
  File "C:\Users\asus\AppData\Roaming\Python\Python310\site-packages\flask\app.py", line 1822, in full_dispatch_request
    rv = self.handle_user_exception(e)
  File "D:\Users\asus\Desktop\youxi\venv\lib\site-packages\flask_cors\extension.py", line 165, in wrapped_function
    return cors_after_request(app.make_response(f(*args, **kwargs)))
  File "C:\Users\asus\AppData\Roaming\Python\Python310\site-packages\flask\app.py", line 1820, in full_dispatch_request
    rv = self.dispatch_request()
  File "C:\Users\asus\AppData\Roaming\Python\Python310\site-packages\flask\app.py", line 1796, in dispatch_request
    return self.ensure_sync(self.view_functions[rule.endpoint])(**view_args)
  File "D:\Users\asus\Desktop\youxi\app\main\exception.py", line 43, in exception_110
    seller_id = orders.query.filter(orders.id == orders_id).first().seller_id
AttributeError: 'NoneType' object has no attribute 'seller_id'
2023-07-06 11:33:38,773 - app - ERROR - Exception on /exception/110 [POST]
Traceback (most recent call last):
  File "C:\Users\asus\AppData\Roaming\Python\Python310\site-packages\flask\app.py", line 2525, in wsgi_app
    response = self.full_dispatch_request()
  File "C:\Users\asus\AppData\Roaming\Python\Python310\site-packages\flask\app.py", line 1822, in full_dispatch_request
    rv = self.handle_user_exception(e)
  File "D:\Users\asus\Desktop\youxi\venv\lib\site-packages\flask_cors\extension.py", line 165, in wrapped_function
    return cors_after_request(app.make_response(f(*args, **kwargs)))
  File "C:\Users\asus\AppData\Roaming\Python\Python310\site-packages\flask\app.py", line 1820, in full_dispatch_request
    rv = self.dispatch_request()
  File "C:\Users\asus\AppData\Roaming\Python\Python310\site-packages\flask\app.py", line 1796, in dispatch_request
    return self.ensure_sync(self.view_functions[rule.endpoint])(**view_args)
  File "D:\Users\asus\Desktop\youxi\app\main\exception.py", line 44, in exception_110
    buyer_id = bids.query.filter(bids.order_id == orders_id).first().buyer_id
AttributeError: 'NoneType' object has no attribute 'buyer_id'
2023-07-06 11:34:18,148 - app - ERROR - Exception on /exception/110 [POST]
Traceback (most recent call last):
  File "C:\Users\asus\AppData\Roaming\Python\Python310\site-packages\flask\app.py", line 2525, in wsgi_app
    response = self.full_dispatch_request()
  File "C:\Users\asus\AppData\Roaming\Python\Python310\site-packages\flask\app.py", line 1822, in full_dispatch_request
    rv = self.handle_user_exception(e)
  File "D:\Users\asus\Desktop\youxi\venv\lib\site-packages\flask_cors\extension.py", line 165, in wrapped_function
    return cors_after_request(app.make_response(f(*args, **kwargs)))
  File "C:\Users\asus\AppData\Roaming\Python\Python310\site-packages\flask\app.py", line 1820, in full_dispatch_request
    rv = self.dispatch_request()
  File "C:\Users\asus\AppData\Roaming\Python\Python310\site-packages\flask\app.py", line 1796, in dispatch_request
    return self.ensure_sync(self.view_functions[rule.endpoint])(**view_args)
  File "D:\Users\asus\Desktop\youxi\app\main\exception.py", line 44, in exception_110
    buyer_id = bids.query.filter(bids.order_id == orders_id).first().buyer_id
AttributeError: 'NoneType' object has no attribute 'buyer_id'
2023-07-06 11:37:37,211 - app - ERROR - Exception on /exception/110 [POST]
Traceback (most recent call last):
  File "C:\Users\asus\AppData\Roaming\Python\Python310\site-packages\flask\app.py", line 2525, in wsgi_app
    response = self.full_dispatch_request()
  File "C:\Users\asus\AppData\Roaming\Python\Python310\site-packages\flask\app.py", line 1822, in full_dispatch_request
    rv = self.handle_user_exception(e)
  File "D:\Users\asus\Desktop\youxi\venv\lib\site-packages\flask_cors\extension.py", line 165, in wrapped_function
    return cors_after_request(app.make_response(f(*args, **kwargs)))
  File "C:\Users\asus\AppData\Roaming\Python\Python310\site-packages\flask\app.py", line 1820, in full_dispatch_request
    rv = self.dispatch_request()
  File "C:\Users\asus\AppData\Roaming\Python\Python310\site-packages\flask\app.py", line 1796, in dispatch_request
    return self.ensure_sync(self.view_functions[rule.endpoint])(**view_args)
  File "D:\Users\asus\Desktop\youxi\app\main\exception.py", line 44, in exception_110
    seller_id = orders.query.filter(orders.id == orders_id).first().seller_id
AttributeError: 'NoneType' object has no attribute 'buyer_id'
2023-07-06 11:37:59,322 - app - ERROR - Exception on /exception/110 [POST]
Traceback (most recent call last):
  File "C:\Users\asus\AppData\Roaming\Python\Python310\site-packages\flask\app.py", line 2525, in wsgi_app
    response = self.full_dispatch_request()
  File "C:\Users\asus\AppData\Roaming\Python\Python310\site-packages\flask\app.py", line 1822, in full_dispatch_request
    rv = self.handle_user_exception(e)
  File "D:\Users\asus\Desktop\youxi\venv\lib\site-packages\flask_cors\extension.py", line 165, in wrapped_function
    return cors_after_request(app.make_response(f(*args, **kwargs)))
  File "C:\Users\asus\AppData\Roaming\Python\Python310\site-packages\flask\app.py", line 1820, in full_dispatch_request
    rv = self.dispatch_request()
  File "C:\Users\asus\AppData\Roaming\Python\Python310\site-packages\flask\app.py", line 1796, in dispatch_request
    return self.ensure_sync(self.view_functions[rule.endpoint])(**view_args)
  File "D:\Users\asus\Desktop\youxi\app\main\exception.py", line 44, in exception_110
    seller_id = orders.query.filter(orders.id == orders_id).first().seller_id
AttributeError: 'NoneType' object has no attribute 'buyer_id'
2023-07-06 11:38:57,215 - app - ERROR - Exception on /exception/110 [POST]
Traceback (most recent call last):
  File "C:\Users\asus\AppData\Roaming\Python\Python310\site-packages\flask\app.py", line 2525, in wsgi_app
    response = self.full_dispatch_request()
  File "C:\Users\asus\AppData\Roaming\Python\Python310\site-packages\flask\app.py", line 1822, in full_dispatch_request
    rv = self.handle_user_exception(e)
  File "D:\Users\asus\Desktop\youxi\venv\lib\site-packages\flask_cors\extension.py", line 165, in wrapped_function
    return cors_after_request(app.make_response(f(*args, **kwargs)))
  File "C:\Users\asus\AppData\Roaming\Python\Python310\site-packages\flask\app.py", line 1820, in full_dispatch_request
    rv = self.dispatch_request()
  File "C:\Users\asus\AppData\Roaming\Python\Python310\site-packages\flask\app.py", line 1796, in dispatch_request
    return self.ensure_sync(self.view_functions[rule.endpoint])(**view_args)
  File "D:\Users\asus\Desktop\youxi\app\main\exception.py", line 44, in exception_110
    seller_id = orders.query.filter(orders.id == orders_id).first().seller_id
AttributeError: 'NoneType' object has no attribute 'buyer_id'
2023-07-08 00:13:27,498 - app - ERROR - this is an error
2023-07-08 00:15:24,936 - app - ERROR - this is an error
2023-07-08 00:24:15,986 - app - ERROR - this is an error
2023-07-08 00:34:38,997 - app - ERROR - this is an error
2023-07-08 00:34:55,626 - app - ERROR - this is an error
2023-07-08 00:50:02,927 - app - ERROR - this is an error
2023-07-08 00:51:08,977 - app - ERROR - this is an error
2023-07-08 00:56:54,511 - app - ERROR - this is an error
2023-07-08 01:01:34,438 - app - ERROR - this is an error
2023-07-08 01:02:40,583 - app - ERROR - this is an error
2023-07-08 01:07:42,130 - app - ERROR - this is an error
2023-07-08 01:20:21,362 - app - ERROR - this is an error
2023-07-08 01:20:42,827 - app - ERROR - this is an error
2023-07-08 01:23:04,284 - app - ERROR - this is an error
2023-07-08 01:24:29,137 - app - ERROR - this is an error
2023-07-08 01:30:32,727 - app - ERROR - this is an error
2023-07-08 01:31:03,534 - app - ERROR - this is an error
2023-07-08 01:31:14,964 - app - ERROR - this is an error
2023-07-08 01:34:25,374 - app - ERROR - this is an error
2023-07-08 01:40:51,178 - app - ERROR - this is an error
2023-07-08 01:42:23,016 - app - ERROR - this is an error
2023-07-08 01:43:56,365 - app - ERROR - this is an error
2023-07-08 01:44:12,137 - app - ERROR - this is an error
2023-07-08 01:46:02,400 - app - ERROR - this is an error
2023-07-08 01:47:57,835 - app - ERROR - this is an error
2023-07-08 01:48:24,717 - app - ERROR - this is an error
